Workbook
Name _: #REF!
Name _: #REF!
Name ____sss111: #REF!
Name ____sss111: #REF!
Name ___SD665: #REF!
Name ___SD665: #REF!
Name ___sss111: #REF!
Name ___sss111: #REF!
Name __2k_pmos: #REF!
Name __2k_pmos: #REF!
Name __3kk_cmos: #REF!
Name __3kk_cmos: #REF!
Name __3kk_pmos: #REF!
Name __3kk_pmos: #REF!
Name __BA02: #REF!
Name __BA02: #REF!
Name __DAT1: #REF!
Name __DAT1: #REF!
Name __DAT10: #REF!
Name __DAT10: #REF!
Name __DAT11: #REF!
Name __DAT11: #REF!
Name __DAT12: #REF!
Name __DAT12: #REF!
Name __DAT13: #REF!
Name __DAT13: #REF!
Name __DAT14: #REF!
Name __DAT14: #REF!
Name __DAT15: #REF!
Name __DAT15: #REF!
Name __DAT16: #REF!
Name __DAT16: #REF!
Name __DAT17: #REF!
Name __DAT17: #REF!
Name __DAT18: #REF!
Name __DAT18: #REF!
Name __DAT2: #REF!
Name __DAT2: #REF!
Name __DAT20: #REF!
Name __DAT20: #REF!
Name __DAT21: #REF!
Name __DAT21: #REF!
Name __DAT22: #REF!
Name __DAT22: #REF!
Name __DAT23: #REF!
Name __DAT23: #REF!
Name __DAT24: #REF!
Name __DAT24: #REF!
Name __DAT25: #REF!
Name __DAT25: #REF!
Name __DAT26: #REF!
Name __DAT26: #REF!
Name __DAT27: #REF!
Name __DAT27: #REF!
Name __DAT3: #REF!
Name __DAT3: #REF!
Name __DAT4: #REF!
Name __DAT4: #REF!
Name __DAT5: #REF!
Name __DAT5: #REF!

Sheet Hisoty
B2: 본 checklist 수정시 관리자와 협의하시기 바랍니다.
B4: Version x.xx | C4: Date yyyy.mm.dd | D4: Description | E4: 관리자
B5: 2 | C5: 2011.03.19 | D5: 도면 승인, 금형/부품개발 일정, 부품승인 명확화를 위한 양식 수정 | E5: 최차림
B6: 3 | C6: 2011.03.31 | D6: 1. Q열에 부품의 변경 정도를 나타내는 "변경 Level" 항목 추가하고, 정의함. 2. 변경 Level이 3이상인 경우는 Base design 검토 결과를 반영하도록 "Base design" work sheet 반영 | E6: 최차림
B7: 3.1 | C7: 2014.11.20 | D7: 인쇄물 변경 여부 추가 | E7: 강정준
B8: 4 | C8: 2022.06.16 | D8: 부품등급 심의회 연동을 위한 양식 수정 및 작성 가이드 명확화 | F8: 22.5/31일 NPI committee 수정 내용 1차 논의, 22.6/3일 SQA, SQE, 개발팀 2차 논의

Sheet 신규_변경부품List v4.0_vf
W2: LREN6325XE(F/S Nova Elec Better)모델 캐나다향 개발을 위한 Panel Assembly 채번 요청드립니다.
F5: Date of compostion: | G5: 45929 | I5: Drafted by: | J5: 나익수S | V5: MDMS3.0에서 모델명 잘못 표기해서 회수한 부품 수정하여 재 요청 해야함
F6: Date of revisions: | G6: 45929 | I6: Revised by: | J6: 나익수S
B7: New & Changing Part Development List
B8: Base Model/Suffix | H8: LDEL7324SE.ASTLLGA
B9: Model/Suffix / Grade | H9: LDEL7324YE.ASTLLGA / Cb
B10: Event | H10: CP PP DV PV PQ
B11: No. | C11: Model | E11: Level | F11: Classification | G11: Part Type | H11: Part No. | J11: Class Desc.(Part Name) | K11: Fig. | L11: Changing Point | M11: Changing Reason | N11: 인쇄물 변경 | O11: Qty | Q11: 변경 부품 대상 | R11: 금형 개발 /수정 | S11: 설계 FMEA 대상 | T11: 공정 FMEA 대상 | U11: 변경 Level | V11: 부품등급 심의회
A12: ㄹ | H12: Base P/No | I12: New P/No | O12: Base | P12: New | V12: 양산처 (기존) | W12: 양산처 (변경) | X12: Cavity정보 (변경 부품 기준) | Y12: 부품 개발 등급 | Z12: 신뢰성검증 프로세스 | AA12: 수율 관리 | AB12: s-APQP | AC12: 공정 FMEA | AD12: 공정심사 or 공장심사 | AE12: 부품 승인 | AF12: 부품 인정 | AG12: 시방 인정 | AH12: 선정 배경
A13: =IF(I13="←",IF(P13="←",0,1),1) -> 1 | B13: 1 | E13: 0 | F13: Changing | H13: LDEL7324SE.ASTLLGA | I13: LDEL7324YE.ASTLLGA | J13: Electric(Freestanding) | O13: 1 | P13: ← | V13: - | W13: -
A14: =IF(I14="←",IF(P14="←",0,1),1) -> 0 | B14: 2 | E14: .1 | F14: Common | H14: ABU74573309 | I14: ← | J14: Cavity Assembly,Full | O14: 1 | P14: ←
A15: =IF(I15="←",IF(P15="←",0,1),1) -> 0 | B15: 3 | E15: ..2 | F15: Common | H15: ABU73833320 | I15: ← | J15: Cavity Assembly,welding | O15: 1 | P15: ←
A16: =IF(I16="←",IF(P16="←",0,1),1) -> 0 | B16: 4 | E16: ...3 | F16: Common | H16: ABU73833318 | I16: ← | J16: Cavity Assembly,welding | O16: 1 | P16: ←
A17: =IF(I17="←",IF(P17="←",0,1),1) -> 0 | B17: 5 | E17: ....4 | F17: Common | H17: MGJ64584202 | I17: ← | J17: Plate,U Bending(Lower) | O17: 1 | P17: ←
A18: =IF(I18="←",IF(P18="←",0,1),1) -> 0 | B18: 6 | E18: .....5 | F18: Common | H18: MGJ64430302 | I18: ← | J18: Plate,Flat(Lower) | O18: 1 | P18: ←
A19: =IF(I19="←",IF(P19="←",0,1),1) -> 0 | B19: 7 | E19: ......6 | F19: Common | H19: RAA33996729 | I19: ← | J19: Sheet,Steel(CR) | O19: 1 | P19: ←
A20: =IF(I20="←",IF(P20="←",0,1),1) -> 0 | B20: 8 | E20: ......6 | F20: Common | H20: RCL30081101 | I20: ← | J20: Coil,Steel(PCM_Product) | O20: 3.4221 | P20: ←
A21: =IF(I21="←",IF(P21="←",0,1),1) -> 0 | B21: 9 | E21: ....4 | F21: Common | H21: MGJ64429402 | I21: ← | J21: Plate,Upper | O21: 1 | P21: ←
A22: =IF(I22="←",IF(P22="←",0,1),1) -> 0 | B22: 10 | E22: .....5 | F22: Common | H22: RAA33996727 | I22: ← | J22: Sheet,Steel(CR) | O22: 1 | P22: ←
A23: =IF(I23="←",IF(P23="←",0,1),1) -> 0 | B23: 11 | E23: .....5 | F23: Common | H23: RCL30081301 | I23: ← | J23: Coil,Steel(PCM_Product) | O23: 2.0135 | P23: ←
A24: =IF(I24="←",IF(P24="←",0,1),1) -> 0 | B24: 12 | E24: ....4 | F24: Common | H24: MGJ64430501 | I24: ← | J24: Plate,Front | O24: 1 | P24: ←
A25: =IF(I25="←",IF(P25="←",0,1),1) -> 0 | B25: 13 | E25: .....5 | F25: Common | H25: RAA33996717 | I25: ← | J25: Sheet,Steel(CR) | O25: 1 | P25: ←
... A284: =IF(I284="←",IF(P284="←",0,1),1) -> 0 | B284: 272 | E284: ...3 | F284: Common | H284: RCL30090301 | I284: ← | J284: Coil,Steel(CR_Product) | O284: 0.059 | P284: ←
A285: =IF(I285="←",IF(P285="←",0,1),1) -> 1 | B285: 273 | E285: .1 | F285: New | H285: ADC30051112 | I285: ADC30051122 | J285: Door Assembly,Full | M285: 하위 부품 변경(Fixed Dimple Handle) | O285: 1 | P285: ← | V285: 기미전자 | W285: 기미전자 | Y285: c | Z285: x | AA285: x | AB285: x | AC285: x | AD285: x | AE285: x | AF285: ○ | AG285: x | AH285: 기존 거래 업체 / 기존 공법 / 기존 재질 적용된 단순 하위 부품 변경 으로 c급 선정
A286: =IF(I286="←",IF(P286="←",0,1),1) -> 0 | B286: 274 | E286: ..2 | F286: Common | H286: AEH76198003 | I286: ← | J286: Hinge Assembly | O286: 2 | P286: ←
A287: =IF(I287="←",IF(P287="←",0,1),1) -> 0 | B287: 275 | E287: ...3 | F287: Common | H287: MEK64466602 | I287: ← | J287: Housing | O287: 1 | P287: ←
A288: =IF(I288="←",IF(P288="←",0,1),1) -> 0 | B288: 276 | E288: ...3 | F288: Common | H288: MEK65197102 | I288: ← | J288: Housing | O288: 1 | P288: ←
A289: =IF(I289="←",IF(P289="←",0,1),1) -> 0 | B289: 277 | E289: ....4 | F289: Common | H289: RCL30078701 | I289: ← | J289: Coil,Steel(GI_Product) | O289: 0.0734 | P289: ←
A290: =IF(I290="←",IF(P290="←",0,1),1) -> 0 | B290: 278 | E290: ...3 | F290: Common | H290: MFC64029503 | I290: ← | J290: Lever | O290: 1 | P290: ←
A291: =IF(I291="←",IF(P291="←",0,1),1) -> 0 | B291: 279 | E291: ...3 | F291: Common | H291: MFG64684601 | I291: ← | J291: Locker | O291: 1 | P291: ←
A292: =IF(I292="←",IF(P292="←",0,1),1) -> 0 | B292: 280 | E292: ...3 | F292: Common | H292: MAK65412401 | I292: ← | J292: Bar,Connector | O292: 1 | P292: ←
A293: =IF(I293="←",IF(P293="←",0,1),1) -> 0 | B293: 281 | E293: ....4 | F293: Common | H293: RCL30076101 | I293: ← | J293: Coil,Steel(CR_Product) | O293: 0.0597 | P293: ←
A294: =IF(I294="←",IF(P294="←",0,1),1) -> 0 | B294: 282 | E294: ..2 | F294: Common | H294: MCK68473501 | I294: ← | J294: Cover,Inner | O294: 1 | P294: ←
A295: =IF(I295="←",IF(P295="←",0,1),1) -> 0 | B295: 283 | E295: ...3 | F295: Common | H295: RAA33956507 | I295: ← | J295: Sheet,Steel(GI) | O295: 1 | P295: ←
A296: =IF(I296="←",IF(P296="←",0,1),1) -> 0 | B296: 284 | E296: ...3 | F296: Common | H296: RCL30080101 | I296: ← | J296: Coil,Steel(PCM_Product) | O296: 0.8847 | P296: ←
A297: =IF(I297="←",IF(P297="←",0,1),1) -> 0 | B297: 285 | E297: ..2 | F297: Common | H297: MAZ64569403 | I297: ← | J297: Bracket,Mount | O297: 2 | P297: ←
... A312: =IF(I312="←",IF(P312="←",0,1),1) -> 0 | B312: 300 | E312: *S* | F312: Common | H312: RAB33372902 | I312: ← | J312: Paint,Powder | O312: 0.1667 | P312: ←
A313: =IF(I313="←",IF(P313="←",0,1),1) -> 1 | B313: 301 | E313: ..2 | F313: New | H313: ADC30051805 | I313: ADC30051810 | J313: Door Assembly,Sub | M313: 하위 부품 변경(Fixed Dimple Handle) | O313: 1 | P313: ← | V313: 기미전자 | W313: 기미전자 | Y313: c | Z313: x | AA313: x | AB313: x | AC313: x | AD313: x | AE313: x | AF313: ○ | AG313: x | AH313: 기존 거래 업체 / 기존 공법 / 기존 재질 적용된 단순 하위 부품 변경 으로 c급 선정
A314: =IF(I314="←",IF(P314="←",0,1),1) -> 1 | B314: 302 | E314: ...3 | F314: New | H314: MCR68408304 | I314: MCR68408309 | J314: Decor,Front | M314: Decor Front 변경 | O314: 1 | P314: ← | V314: 기미전자 | W314: 기미전자 | Y314: c | Z314: x | AA314: x | AB314: x | AC314: x | AD314: x | AE314: x | AF314: ○ | AG314: x | AH314: 기존 거래 업체 / 기존 공법 / 기존 재질 적용된 단순 하위 부품 변경 으로 c급 선정
A315: =IF(I315="←",IF(P315="←",0,1),1) -> 0 | B315: 303 | E315: ....4 | F315: Common | H315: RSH31038802 | I315: ← | J315: Sheet,Steel(STS) | O315: 1 | P315: ←
...

Sheet 부품등급심의회회의록
A1: Project명 | B1: Lupin2 F/S Elec Double Good+ Transition | E1: Model | F1: ='신규_변경부품List v4.0_vf'!I13 -> LDEL7324YE.ASTLLGA | J1: 개발등급 | K1: Cb급
A2: 일정 | B2: 2025.11.07 | E2: 참석자 | F2: 제품개발 : 조상혁 연구원 부품품질 : 김기환 책임 개발구매 : 류동건S
A5: 장소 | B5: 선진화동 4F | E5: 회의록 | F5: 1. 부품등급심의 결과 - 신규부품 20개 (c급 15개, d급 5개) 2. 부품인정시험 대상 부품 : 14 ea (제어 : 0 ea / 전장 : 0ea / 기구 : 14 ea) 3. 한도승인 대상 부품 : 2 ea 4. 수율 검증 대상 부품 없음
A8: 협력회사 | B8: 부품명 | C8: Part No | E8: 부품 개발 등급 | F8: 신뢰성 9 Step | G8: 수율 관리 | H8: s-APQP | I8: 공정 DRBFM | J8: 공정심사 or 공장심사 | K8: 부품 승인 | L8: 부품 인정 | M8: 시방 인정 | N8: 선정 배경
A9: {=IFERROR(INDEX('신규_변경부품List v4.0_vf'!$W$13:$W$765,1/LARGE(INDEX(('신규_변경부품List v4.0_vf'!$AF$13:$AF$765="○")/ROW('신규_변경부품List v4.0_vf'!$AF$13:$AF$765),),ROW('신규_변경부품List v4.0_vf'!$A1))-12,1),"")} -> 기미전자 | B9: {=IFERROR(INDEX('신규_변경부품List v4.0_vf'!$J$13:$J$765,1/LARGE(INDEX(('신규_변경부품List v4.0_vf'!$AF$13:$AF$765="○")/ROW('신규_변경부품List v4.0_vf'!$AF$13:$AF$765),),ROW('신규_변경부품List v4.0_vf'!$A1))-12,1),"")} -> Door Assembly,Full | C9: {=IFERROR(INDEX('신규_변경부품List v4.0_vf'!$I$13:$I$765,1/LARGE(INDEX(('신규_변경부품List v4.0_vf'!$AF$13:$AF$765="○")/ROW('신규_변경부품List v4.0_vf'!$AF$13:$AF$765),),ROW('신규_변경부품List v4.0_vf'!$A1))-12,1),"")} -> ADC30051122 | D9: =COUNTIF($C$1:$C8,C9) -> 0 | E9: {=IFERROR(INDEX('신규_변경부품List v4.0_vf'!Y$13:Y$765,1/LARGE(INDEX(('신규_변경부품List v4.0_vf'!$AF$13:$AF$765="○")/ROW('신규_변경부품List v4.0_vf'!$AF$13:$AF$765),),ROW('신규_변경부품List v4.0_vf'!$A1))-12,1),"")} -> c | F9: {=IFERROR(INDEX('신규_변경부품List v4.0_vf'!Z$13:Z$765,1/LARGE(INDEX(('신규_변경부품List v4.0_vf'!$AF$13:$AF$765="○")/ROW('신규_변경부품List v4.0_vf'!$AF$13:$AF$765),),ROW('신규_변경부품List v4.0_vf'!$A1))-12,1),"")} -> x | G9: {=IFERROR(INDEX('신규_변경부품List v4.0_vf'!AA$13:AA$765,1/LARGE(INDEX(('신규_변경부품List v4.0_vf'!$AF$13:$AF$765="○")/ROW('신규_변경부품List v4.0_vf'!$AF$13:$AF$765),),ROW('신규_변경부품List v4.0_vf'!$A1))-12,1),"")} -> x | H9: {=IFERROR(INDEX('신규_변경부품List v4.0_vf'!AB$13:AB$765,1/LARGE(INDEX(('신규_변경부품List v4.0_vf'!$AF$13:$AF$765="○")/ROW('신규_변경부품List v4.0_vf'!$AF$13:$AF$765),),ROW('신규_변경부품List v4.0_vf'!$A1))-12,1),"")} -> x | I9: {=IFERROR(INDEX('신규_변경부품List v4.0_vf'!AC$13:AC$765,1/LARGE(INDEX(('신규_변경부품List v4.0_vf'!$AF$13:$AF$765="○")/ROW('신규_변경부품List v4.0_vf'!$AF$13:$AF$765),),ROW('신규_변경부품List v4.0_vf'!$A1))-12,1),"")} -> x | J9: {=IFERROR(INDEX('신규_변경부품List v4.0_vf'!AD$13:AD$765,1/LARGE(INDEX(('신규_변경부품List v4.0_vf'!$AF$13:$AF$765="○")/ROW('신규_변경부품List v4.0_vf'!$AF$13:$AF$765),),ROW('신규_변경부품List v4.0_vf'!$A1))-12,1),"")} -> x | K9: {=IFERROR(INDEX('신규_변경부품List v4.0_vf'!AE$13:AE$765,1/LARGE(INDEX(('신규_변경부품List v4.0_vf'!$AF$13:$AF$765="○")/ROW('신규_변경부품List v4.0_vf'!$AF$13:$AF$765),),ROW('신규_변경부품List v4.0_vf'!$A1))-12,1),"")} -> x | L9: {=IFERROR(INDEX('신규_변경부품List v4.0_vf'!AF$13:AF$765,1/LARGE(INDEX(('신규_변경부품List v4.0_vf'!$AF$13:$AF$765="○")/ROW('신규_변경부품List v4.0_vf'!$AF$13:$AF$765),),ROW('신규_변경부품List v4.0_vf'!$A1))-12,1),"")} -> ○ | ... N9: {=IFERROR(INDEX('신규_변경부품List v4.0_vf'!AH$13:AH$765,1/LARGE(INDEX(('신규_변경부품List v4.0_vf'!$AF$13:$AF$765="○")/ROW('신규_변경부품List v4.0_vf'!$AF$13:$AF$765),),ROW('신규_변경부품List v4.0_vf'!$A1))-12,1),"")} -> 기존 거래 업체 / 기존 공법 / 기존 재질 적용된 단순 하위 부품 변경 으로 c급 선정
A10: {=IFERROR(INDEX('신규_변경부품List v4.0_vf'!$W$13:$W$765,1/LARGE(INDEX(('신규_변경부품List v4.0_vf'!$AF$13:$AF$765="○")/ROW('신규_변경부품List v4.0_vf'!$AF$13:$AF$765),),ROW('신규_변경부품List v4.0_vf'!$A2))-12,1),"")} -> 기미전자 | B10: {=IFERROR(INDEX('신규_변경부품List v4.0_vf'!$J$13:$J$765,1/LARGE(INDEX(('신규_변경부품List v4.0_vf'!$AF$13:$AF$765="○")/ROW('신규_변경부품List v4.0_vf'!$AF$13:$AF$765),),ROW('신규_변경부품List v4.0_vf'!$A2))-12,1),"")} -> Door Assembly,Sub | C10: {=IFERROR(INDEX('신규_변경부품List v4.0_vf'!$I$13:$I$765,1/LARGE(INDEX(('신규_변경부품List v4.0_vf'!$AF$13:$AF$765="○")/ROW('신규_변경부품List v4.0_vf'!$AF$13:$AF$765),),ROW('신규_변경부품List v4.0_vf'!$A2))-12,1),"")} -> ADC30051810 | D10: =COUNTIF($C$1:$C9,C10) -> 0 | E10: {=IFERROR(INDEX('신규_변경부품List v4.0_vf'!Y$13:Y$765,1/LARGE(INDEX(('신규_변경부품List v4.0_vf'!$AF$13:$AF$765="○")/ROW('신규_변경부품List v4.0_vf'!$AF$13:$AF$765),),ROW('신규_변경부품List v4.0_vf'!$A2))-12,1),"")} -> c | F10: {=IFERROR(INDEX('신규_변경부품List v4.0_vf'!Z$13:Z$765,1/LARGE(INDEX(('신규_변경부품List v4.0_vf'!$AF$13:$AF$765="○")/ROW('신규_변경부품List v4.0_vf'!$AF$13:$AF$765),),ROW('신규_변경부품List v4.0_vf'!$A2))-12,1),"")} -> x | G10: {=IFERROR(INDEX('신규_변경부품List v4.0_vf'!AA$13:AA$765,1/LARGE(INDEX(('신규_변경부품List v4.0_vf'!$AF$13:$AF$765="○")/ROW('신규_변경부품List v4.0_vf'!$AF$13:$AF$765),),ROW('신규_변경부품List v4.0_vf'!$A2))-12,1),"")} -> x | H10: {=IFERROR(INDEX('신규_변경부품List v4.0_vf'!AB$13:AB$765,1/LARGE(INDEX(('신규_변경부품List v4.0_vf'!$AF$13:$AF$765="○")/ROW('신규_변경부품List v4.0_vf'!$AF$13:$AF$765),),ROW('신규_변경부품List v4.0_vf'!$A2))-12,1),"")} -> x | I10: {=IFERROR(INDEX('신규_변경부품List v4.0_vf'!AC$13:AC$765,1/LARGE(INDEX(('신규_변경부품List v4.0_vf'!$AF$13:$AF$765="○")/ROW('신규_변경부품List v4.0_vf'!$AF$13:$AF$765),),ROW('신규_변경부품List v4.0_vf'!$A2))-12,1),"")} -> x | J10: {=IFERROR(INDEX('신규_변경부품List v4.0_vf'!AD$13:AD$765,1/LARGE(INDEX(('신규_변경부품List v4.0_vf'!$AF$13:$AF$765="○")/ROW('신규_변경부품List v4.0_vf'!$AF$13:$AF$765),),ROW('신규_변경부품List v4.0_vf'!$A2))-12,1),"")} -> x | K10: {=IFERROR(INDEX('신규_변경부품List v4.0_vf'!AE$13:AE$765,1/LARGE(INDEX(('신규_변경부품List v4.0_vf'!$AF$13:$AF$765="○")/ROW('신규_변경부품List v4.0_vf'!$AF$13:$AF$765),),ROW('신규_변경부품List v4.0_vf'!$A2))-12,1),"")} -> x | L10: {=IFERROR(INDEX('신규_변경부품List v4.0_vf'!AF$13:AF$765,1/LARGE(INDEX(('신규_변경부품List v4.0_vf'!$AF$13:$AF$765="○")/ROW('신규_변경부품List v4.0_vf'!$AF$13:$AF$765),),ROW('신규_변경부품List v4.0_vf'!$A2))-12,1),"")} -> ○ | ... N10: {=IFERROR(INDEX('신규_변경부품List v4.0_vf'!AH$13:AH$765,1/LARGE(INDEX(('신규_변경부품List v4.0_vf'!$AF$13:$AF$765="○")/ROW('신규_변경부품List v4.0_vf'!$AF$13:$AF$765),),ROW('신규_변경부품List v4.0_vf'!$A2))-12,1),"")} -> 기존 거래 업체 / 기존 공법 / 기존 재질 적용된 단순 하위 부품 변경 으로 c급 선정
A11: {=IFERROR(INDEX('신규_변경부품List v4.0_vf'!$W$13:$W$765,1/LARGE(INDEX(('신규_변경부품List v4.0_vf'!$AF$13:$AF$765="○")/ROW('신규_변경부품List v4.0_vf'!$AF$13:$AF$765),),ROW('신규_변경부품List v4.0_vf'!$A3))-12,1),"")} -> 기미전자 | B11: {=IFERROR(INDEX('신규_변경부품List v4.0_vf'!$J$13:$J$765,1/LARGE(INDEX(('신규_변경부품List v4.0_vf'!$AF$13:$AF$765="○")/ROW('신규_변경부품List v4.0_vf'!$AF$13:$AF$765),),ROW('신규_변경부품List v4.0_vf'!$A3))-12,1),"")} -> Decor,Front | C11: {=IFERROR(INDEX('신규_변경부품List v4.0_vf'!$I$13:$I$765,1/LARGE(INDEX(('신규_변경부품List v4.0_vf'!$AF$13:$AF$765="○")/ROW('신규_변경부품List v4.0_vf'!$AF$13:$AF$765),),ROW('신규_변경부품List v4.0_vf'!$A3))-12,1),"")} -> MCR68408309 | D11: =COUNTIF($C$1:$C10,C11) -> 0 | E11: {=IFERROR(INDEX('신규_변경부품List v4.0_vf'!Y$13:Y$765,1/LARGE(INDEX(('신규_변경부품List v4.0_vf'!$AF$13:$AF$765="○")/ROW('신규_변경부품List v4.0_vf'!$AF$13:$AF$765),),ROW('신규_변경부품List v4.0_vf'!$A3))-12,1),"")} -> c | F11: {=IFERROR(INDEX('신규_변경부품List v4.0_vf'!Z$13:Z$765,1/LARGE(INDEX(('신규_변경부품List v4.0_vf'!$AF$13:$AF$765="○")/ROW('신규_변경부품List v4.0_vf'!$AF$13:$AF$765),),ROW('신규_변경부품List v4.0_vf'!$A3))-12,1),"")} -> x | G11: {=IFERROR(INDEX('신규_변경부품List v4.0_vf'!AA$13:AA$765,1/LARGE(INDEX(('신규_변경부품List v4.0_vf'!$AF$13:$AF$765="○")/ROW('신규_변경부품List v4.0_vf'!$AF$13:$AF$765),),ROW('신규_변경부품List v4.0_vf'!$A3))-12,1),"")} -> x | H11: {=IFERROR(INDEX('신규_변경부품List v4.0_vf'!AB$13:AB$765,1/LARGE(INDEX(('신규_변경부품List v4.0_vf'!$AF$13:$AF$765="○")/ROW('신규_변경부품List v4.0_vf'!$AF$13:$AF$765),),ROW('신규_변경부품List v4.0_vf'!$A3))-12,1),"")} -> x | I11: {=IFERROR(INDEX('신규_변경부품List v4.0_vf'!AC$13:AC$765,1/LARGE(INDEX(('신규_변경부품List v4.0_vf'!$AF$13:$AF$765="○")/ROW('신규_변경부품List v4.0_vf'!$AF$13:$AF$765),),ROW('신규_변경부품List v4.0_vf'!$A3))-12,1),"")} -> x | J11: {=IFERROR(INDEX('신규_변경부품List v4.0_vf'!AD$13:AD$765,1/LARGE(INDEX(('신규_변경부품List v4.0_vf'!$AF$13:$AF$765="○")/ROW('신규_변경부품List v4.0_vf'!$AF$13:$AF$765),),ROW('신규_변경부품List v4.0_vf'!$A3))-12,1),"")} -> x | K11: {=IFERROR(INDEX('신규_변경부품List v4.0_vf'!AE$13:AE$765,1/LARGE(INDEX(('신규_변경부품List v4.0_vf'!$AF$13:$AF$765="○")/ROW('신규_변경부품List v4.0_vf'!$AF$13:$AF$765),),ROW('신규_변경부품List v4.0_vf'!$A3))-12,1),"")} -> x | L11: {=IFERROR(INDEX('신규_변경부품List v4.0_vf'!AF$13:AF$765,1/LARGE(INDEX(('신규_변경부품List v4.0_vf'!$AF$13:$AF$765="○")/ROW('신규_변경부품List v4.0_vf'!$AF$13:$AF$765),),ROW('신규_변경부품List v4.0_vf'!$A3))-12,1),"")} -> ○ | ... N11: {=IFERROR(INDEX('신규_변경부품List v4.0_vf'!AH$13:AH$765,1/LARGE(INDEX(('신규_변경부품List v4.0_vf'!$AF$13:$AF$765="○")/ROW('신규_변경부품List v4.0_vf'!$AF$13:$AF$765),),ROW('신규_변경부품List v4.0_vf'!$A3))-12,1),"")} -> 기존 거래 업체 / 기존 공법 / 기존 재질 적용된 단순 하위 부품 변경 으로 c급 선정
A12: {=IFERROR(INDEX('신규_변경부품List v4.0_vf'!$W$13:$W$765,1/LARGE(INDEX(('신규_변경부품List v4.0_vf'!$AF$13:$AF$765="○")/ROW('신규_변경부품List v4.0_vf'!$AF$13:$AF$765),),ROW('신규_변경부품List v4.0_vf'!$A4))-12,1),"")} -> 에스디이앤티(한덕) | B12: {=IFERROR(INDEX('신규_변경부품List v4.0_vf'!$J$13:$J$765,1/LARGE(INDEX(('신규_변경부품List v4.0_vf'!$AF$13:$AF$765="○")/ROW('신규_변경부품List v4.0_vf'!$AF$13:$AF$765),),ROW('신규_변경부품List v4.0_vf'!$A4))-12,1),"")} -> Handle,Door | C12: {=IFERROR(INDEX('신규_변경부품List v4.0_vf'!$I$13:$I$765,1/LARGE(INDEX(('신규_변경부품List v4.0_vf'!$AF$13:$AF$765="○")/ROW('신규_변경부품List v4.0_vf'!$AF$13:$AF$765),),ROW('신규_변경부품List v4.0_vf'!$A4))-12,1),"")} -> AED30153303 | D12: =COUNTIF($C$1:$C11,C12) -> 0 | E12: {=IFERROR(INDEX('신규_변경부품List v4.0_vf'!Y$13:Y$765,1/LARGE(INDEX(('신규_변경부품List v4.0_vf'!$AF$13:$AF$765="○")/ROW('신규_변경부품List v4.0_vf'!$AF$13:$AF$765),),ROW('신규_변경부품List v4.0_vf'!$A4))-12,1),"")} -> c | F12: {=IFERROR(INDEX('신규_변경부품List v4.0_vf'!Z$13:Z$765,1/LARGE(INDEX(('신규_변경부품List v4.0_vf'!$AF$13:$AF$765="○")/ROW('신규_변경부품List v4.0_vf'!$AF$13:$AF$765),),ROW('신규_변경부품List v4.0_vf'!$A4))-12,1),"")} -> x | G12: {=IFERROR(INDEX('신규_변경부품List v4.0_vf'!AA$13:AA$765,1/LARGE(INDEX(('신규_변경부품List v4.0_vf'!$AF$13:$AF$765="○")/ROW('신규_변경부품List v4.0_vf'!$AF$13:$AF$765),),ROW('신규_변경부품List v4.0_vf'!$A4))-12,1),"")} -> x | H12: {=IFERROR(INDEX('신규_변경부품List v4.0_vf'!AB$13:AB$765,1/LARGE(INDEX(('신규_변경부품List v4.0_vf'!$AF$13:$AF$765="○")/ROW('신규_변경부품List v4.0_vf'!$AF$13:$AF$765),),ROW('신규_변경부품List v4.0_vf'!$A4))-12,1),"")} -> x | I12: {=IFERROR(INDEX('신규_변경부품List v4.0_vf'!AC$13:AC$765,1/LARGE(INDEX(('신규_변경부품List v4.0_vf'!$AF$13:$AF$765="○")/ROW('신규_변경부품List v4.0_vf'!$AF$13:$AF$765),),ROW('신규_변경부품List v4.0_vf'!$A4))-12,1),"")} -> x | J12: {=IFERROR(INDEX('신규_변경부품List v4.0_vf'!AD$13:AD$765,1/LARGE(INDEX(('신규_변경부품List v4.0_vf'!$AF$13:$AF$765="○")/ROW('신규_변경부품List v4.0_vf'!$AF$13:$AF$765),),ROW('신규_변경부품List v4.0_vf'!$A4))-12,1),"")} -> x | K12: {=IFERROR(INDEX('신규_변경부품List v4.0_vf'!AE$13:AE$765,1/LARGE(INDEX(('신규_변경부품List v4.0_vf'!$AF$13:$AF$765="○")/ROW('신규_변경부품List v4.0_vf'!$AF$13:$AF$765),),ROW('신규_변경부품List v4.0_vf'!$A4))-12,1),"")} -> x | L12: {=IFERROR(INDEX('신규_변경부품List v4.0_vf'!AF$13:AF$765,1/LARGE(INDEX(('신규_변경부품List v4.0_vf'!$AF$13:$AF$765="○")/ROW('신규_변경부품List v4.0_vf'!$AF$13:$AF$765),),ROW('신규_변경부품List v4.0_vf'!$A4))-12,1),"")} -> ○ | ... N12: {=IFERROR(INDEX('신규_변경부품List v4.0_vf'!AH$13:AH$765,1/LARGE(INDEX(('신규_변경부품List v4.0_vf'!$AF$13:$AF$765="○")/ROW('신규_변경부품List v4.0_vf'!$AF$13:$AF$765),),ROW('신규_변경부품List v4.0_vf'!$A4))-12,1),"")} -> 기존 거래 업체 / 기존 공법 / 기존 재질 적용된 단순 하위 부품 변경 으로 c급 선정
A13: {=IFERROR(INDEX('신규_변경부품List v4.0_vf'!$W$13:$W$765,1/LARGE(INDEX(('신규_변경부품List v4.0_vf'!$AF$13:$AF$765="○")/ROW('신규_변경부품List v4.0_vf'!$AF$13:$AF$765),),ROW('신규_변경부품List v4.0_vf'!$A5))-12,1),"")} -> 에스디이앤티(한덕) | B13: {=IFERROR(INDEX('신규_변경부품List v4.0_vf'!$J$13:$J$765,1/LARGE(INDEX(('신규_변경부품List v4.0_vf'!$AF$13:$AF$765="○")/ROW('신규_변경부품List v4.0_vf'!$AF$13:$AF$765),),ROW('신규_변경부품List v4.0_vf'!$A5))-12,1),"")} -> Holder,Bracket | C13: {=IFERROR(INDEX('신규_변경부품List v4.0_vf'!$I$13:$I$765,1/LARGE(INDEX(('신규_변경부품List v4.0_vf'!$AF$13:$AF$765="○")/ROW('신규_변경부품List v4.0_vf'!$AF$13:$AF$765),),ROW('신규_변경부품List v4.0_vf'!$A5))-12,1),"")} -> MEG66749803 | D13: =COUNTIF($C$1:$C12,C13) -> 0 | E13: {=IFERROR(INDEX('신규_변경부품List v4.0_vf'!Y$13:Y$765,1/LARGE(INDEX(('신규_변경부품List v4.0_vf'!$AF$13:$AF$765="○")/ROW('신규_변경부품List v4.0_vf'!$AF$13:$AF$765),),ROW('신규_변경부품List v4.0_vf'!$A5))-12,1),"")} -> c | F13: {=IFERROR(INDEX('신규_변경부품List v4.0_vf'!Z$13:Z$765,1/LARGE(INDEX(('신규_변경부품List v4.0_vf'!$AF$13:$AF$765="○")/ROW('신규_변경부품List v4.0_vf'!$AF$13:$AF$765),),ROW('신규_변경부품List v4.0_vf'!$A5))-12,1),"")} -> x | G13: {=IFERROR(INDEX('신규_변경부품List v4.0_vf'!AA$13:AA$765,1/LARGE(INDEX(('신규_변경부품List v4.0_vf'!$AF$13:$AF$765="○")/ROW('신규_변경부품List v4.0_vf'!$AF$13:$AF$765),),ROW('신규_변경부품List v4.0_vf'!$A5))-12,1),"")} -> x | H13: {=IFERROR(INDEX('신규_변경부품List v4.0_vf'!AB$13:AB$765,1/LARGE(INDEX(('신규_변경부품List v4.0_vf'!$AF$13:$AF$765="○")/ROW('신규_변경부품List v4.0_vf'!$AF$13:$AF$765),),ROW('신규_변경부품List v4.0_vf'!$A5))-12,1),"")} -> x | I13: {=IFERROR(INDEX('신규_변경부품List v4.0_vf'!AC$13:AC$765,1/LARGE(INDEX(('신규_변경부품List v4.0_vf'!$AF$13:$AF$765="○")/ROW('신규_변경부품List v4.0_vf'!$AF$13:$AF$765),),ROW('신규_변경부품List v4.0_vf'!$A5))-12,1),"")} -> x | J13: {=IFERROR(INDEX('신규_변경부품List v4.0_vf'!AD$13:AD$765,1/LARGE(INDEX(('신규_변경부품List v4.0_vf'!$AF$13:$AF$765="○")/ROW('신규_변경부품List v4.0_vf'!$AF$13:$AF$765),),ROW('신규_변경부품List v4.0_vf'!$A5))-12,1),"")} -> x | K13: {=IFERROR(INDEX('신규_변경부품List v4.0_vf'!AE$13:AE$765,1/LARGE(INDEX(('신규_변경부품List v4.0_vf'!$AF$13:$AF$765="○")/ROW('신규_변경부품List v4.0_vf'!$AF$13:$AF$765),),ROW('신규_변경부품List v4.0_vf'!$A5))-12,1),"")} -> x | L13: {=IFERROR(INDEX('신규_변경부품List v4.0_vf'!AF$13:AF$765,1/LARGE(INDEX(('신규_변경부품List v4.0_vf'!$AF$13:$AF$765="○")/ROW('신규_변경부품List v4.0_vf'!$AF$13:$AF$765),),ROW('신규_변경부품List v4.0_vf'!$A5))-12,1),"")} -> ○ | ... N13: {=IFERROR(INDEX('신규_변경부품List v4.0_vf'!AH$13:AH$765,1/LARGE(INDEX(('신규_변경부품List v4.0_vf'!$AF$13:$AF$765="○")/ROW('신규_변경부품List v4.0_vf'!$AF$13:$AF$765),),ROW('신규_변경부품List v4.0_vf'!$A5))-12,1),"")} -> 기존 거래 업체 / 기존 공법 / 기존 재질 적용된 단순 하위 부품 변경 으로 c급 선정
A14: {=IFERROR(INDEX('신규_변경부품List v4.0_vf'!$W$13:$W$765,1/LARGE(INDEX(('신규_변경부품List v4.0_vf'!$AF$13:$AF$765="○")/ROW('신규_변경부품List v4.0_vf'!$AF$13:$AF$765),),ROW('신규_변경부품List v4.0_vf'!$A6))-12,1),"")} -> 서브원(세광러버테크) | B14: {=IFERROR(INDEX('신규_변경부품List v4.0_vf'!$J$13:$J$765,1/LARGE(INDEX(('신규_변경부품List v4.0_vf'!$AF$13:$AF$765="○")/ROW('신규_변경부품List v4.0_vf'!$AF$13:$AF$765),),ROW('신규_변경부품List v4.0_vf'!$A6))-12,1),"")} -> Packing,Gasket | C14: {=IFERROR(INDEX('신규_변경부품List v4.0_vf'!$I$13:$I$765,1/LARGE(INDEX(('신규_변경부품List v4.0_vf'!$AF$13:$AF$765="○")/ROW('신규_변경부품List v4.0_vf'!$AF$13:$AF$765),),ROW('신규_변경부품List v4.0_vf'!$A6))-12,1),"")} -> MFZ00552701 | D14: =COUNTIF($C$1:$C13,C14) -> 0 | E14: {=IFERROR(INDEX('신규_변경부품List v4.0_vf'!Y$13:Y$765,1/LARGE(INDEX(('신규_변경부품List v4.0_vf'!$AF$13:$AF$765="○")/ROW('신규_변경부품List v4.0_vf'!$AF$13:$AF$765),),ROW('신규_변경부품List v4.0_vf'!$A6))-12,1),"")} -> c | F14: {=IFERROR(INDEX('신규_변경부품List v4.0_vf'!Z$13:Z$765,1/LARGE(INDEX(('신규_변경부품List v4.0_vf'!$AF$13:$AF$765="○")/ROW('신규_변경부품List v4.0_vf'!$AF$13:$AF$765),),ROW('신규_변경부품List v4.0_vf'!$A6))-12,1),"")} -> x | G14: {=IFERROR(INDEX('신규_변경부품List v4.0_vf'!AA$13:AA$765,1/LARGE(INDEX(('신규_변경부품List v4.0_vf'!$AF$13:$AF$765="○")/ROW('신규_변경부품List v4.0_vf'!$AF$13:$AF$765),),ROW('신규_변경부품List v4.0_vf'!$A6))-12,1),"")} -> x | H14: {=IFERROR(INDEX('신규_변경부품List v4.0_vf'!AB$13:AB$765,1/LARGE(INDEX(('신규_변경부품List v4.0_vf'!$AF$13:$AF$765="○")/ROW('신규_변경부품List v4.0_vf'!$AF$13:$AF$765),),ROW('신규_변경부품List v4.0_vf'!$A6))-12,1),"")} -> x | I14: {=IFERROR(INDEX('신규_변경부품List v4.0_vf'!AC$13:AC$765,1/LARGE(INDEX(('신규_변경부품List v4.0_vf'!$AF$13:$AF$765="○")/ROW('신규_변경부품List v4.0_vf'!$AF$13:$AF$765),),ROW('신규_변경부품List v4.0_vf'!$A6))-12,1),"")} -> x | J14: {=IFERROR(INDEX('신규_변경부품List v4.0_vf'!AD$13:AD$765,1/LARGE(INDEX(('신규_변경부품List v4.0_vf'!$AF$13:$AF$765="○")/ROW('신규_변경부품List v4.0_vf'!$AF$13:$AF$765),),ROW('신규_변경부품List v4.0_vf'!$A6))-12,1),"")} -> x | K14: {=IFERROR(INDEX('신규_변경부품List v4.0_vf'!AE$13:AE$765,1/LARGE(INDEX(('신규_변경부품List v4.0_vf'!$AF$13:$AF$765="○")/ROW('신규_변경부품List v4.0_vf'!$AF$13:$AF$765),),ROW('신규_변경부품List v4.0_vf'!$A6))-12,1),"")} -> x | L14: {=IFERROR(INDEX('신규_변경부품List v4.0_vf'!AF$13:AF$765,1/LARGE(INDEX(('신규_변경부품List v4.0_vf'!$AF$13:$AF$765="○")/ROW('신규_변경부품List v4.0_vf'!$AF$13:$AF$765),),ROW('신규_변경부품List v4.0_vf'!$A6))-12,1),"")} -> ○ | ... N14: {=IFERROR(INDEX('신규_변경부품List v4.0_vf'!AH$13:AH$765,1/LARGE(INDEX(('신규_변경부품List v4.0_vf'!$AF$13:$AF$765="○")/ROW('신규_변경부품List v4.0_vf'!$AF$13:$AF$765),),ROW('신규_변경부품List v4.0_vf'!$A6))-12,1),"")} -> 기존 거래 업체 / 기존 공법 / 기존 재질 적용된 단순 하위 부품 변경 으로 c급 선정
A15: {=IFERROR(INDEX('신규_변경부품List v4.0_vf'!$W$13:$W$765,1/LARGE(INDEX(('신규_변경부품List v4.0_vf'!$AF$13:$AF$765="○")/ROW('신규_변경부품List v4.0_vf'!$AF$13:$AF$765),),ROW('신규_변경부품List v4.0_vf'!$A7))-12,1),"")} -> 기미전자 | B15: {=IFERROR(INDEX('신규_변경부품List v4.0_vf'!$J$13:$J$765,1/LARGE(INDEX(('신규_변경부품List v4.0_vf'!$AF$13:$AF$765="○")/ROW('신규_변경부품List v4.0_vf'!$AF$13:$AF$765),),ROW('신규_변경부품List v4.0_vf'!$A7))-12,1),"")} -> Door Assembly,Full | C15: {=IFERROR(INDEX('신규_변경부품List v4.0_vf'!$I$13:$I$765,1/LARGE(INDEX(('신규_변경부품List v4.0_vf'!$AF$13:$AF$765="○")/ROW('신규_변경부품List v4.0_vf'!$AF$13:$AF$765),),ROW('신규_변경부품List v4.0_vf'!$A7))-12,1),"")} -> ADC30051023 | D15: =COUNTIF($C$1:$C14,C15) -> 0 | E15: {=IFERROR(INDEX('신규_변경부품List v4.0_vf'!Y$13:Y$765,1/LARGE(INDEX(('신규_변경부품List v4.0_vf'!$AF$13:$AF$765="○")/ROW('신규_변경부품List v4.0_vf'!$AF$13:$AF$765),),ROW('신규_변경부품List v4.0_vf'!$A7))-12,1),"")} -> c | F15: {=IFERROR(INDEX('신규_변경부품List v4.0_vf'!Z$13:Z$765,1/LARGE(INDEX(('신규_변경부품List v4.0_vf'!$AF$13:$AF$765="○")/ROW('신규_변경부품List v4.0_vf'!$AF$13:$AF$765),),ROW('신규_변경부품List v4.0_vf'!$A7))-12,1),"")} -> x | G15: {=IFERROR(INDEX('신규_변경부품List v4.0_vf'!AA$13:AA$765,1/LARGE(INDEX(('신규_변경부품List v4.0_vf'!$AF$13:$AF$765="○")/ROW('신규_변경부품List v4.0_vf'!$AF$13:$AF$765),),ROW('신규_변경부품List v4.0_vf'!$A7))-12,1),"")} -> x | H15: {=IFERROR(INDEX('신규_변경부품List v4.0_vf'!AB$13:AB$765,1/LARGE(INDEX(('신규_변경부품List v4.0_vf'!$AF$13:$AF$765="○")/ROW('신규_변경부품List v4.0_vf'!$AF$13:$AF$765),),ROW('신규_변경부품List v4.0_vf'!$A7))-12,1),"")} -> x | I15: {=IFERROR(INDEX('신규_변경부품List v4.0_vf'!AC$13:AC$765,1/LARGE(INDEX(('신규_변경부품List v4.0_vf'!$AF$13:$AF$765="○")/ROW('신규_변경부품List v4.0_vf'!$AF$13:$AF$765),),ROW('신규_변경부품List v4.0_vf'!$A7))-12,1),"")} -> x | J15: {=IFERROR(INDEX('신규_변경부품List v4.0_vf'!AD$13:AD$765,1/LARGE(INDEX(('신규_변경부품List v4.0_vf'!$AF$13:$AF$765="○")/ROW('신규_변경부품List v4.0_vf'!$AF$13:$AF$765),),ROW('신규_변경부품List v4.0_vf'!$A7))-12,1),"")} -> x | K15: {=IFERROR(INDEX('신규_변경부품List v4.0_vf'!AE$13:AE$765,1/LARGE(INDEX(('신규_변경부품List v4.0_vf'!$AF$13:$AF$765="○")/ROW('신규_변경부품List v4.0_vf'!$AF$13:$AF$765),),ROW('신규_변경부품List v4.0_vf'!$A7))-12,1),"")} -> x | L15: {=IFERROR(INDEX('신규_변경부품List v4.0_vf'!AF$13:AF$765,1/LARGE(INDEX(('신규_변경부품List v4.0_vf'!$AF$13:$AF$765="○")/ROW('신규_변경부품List v4.0_vf'!$AF$13:$AF$765),),ROW('신규_변경부품List v4.0_vf'!$A7))-12,1),"")} -> ○ | ... N15: {=IFERROR(INDEX('신규_변경부품List v4.0_vf'!AH$13:AH$765,1/LARGE(INDEX(('신규_변경부품List v4.0_vf'!$AF$13:$AF$765="○")/ROW('신규_변경부품List v4.0_vf'!$AF$13:$AF$765),),ROW('신규_변경부품List v4.0_vf'!$A7))-12,1),"")} -> 기존 거래 업체 / 기존 공법 / 기존 재질 적용된 단순 하위 부품 변경 으로 c급 선정
A16: {=IFERROR(INDEX('신규_변경부품List v4.0_vf'!$W$13:$W$765,1/LARGE(INDEX(('신규_변경부품List v4.0_vf'!$AF$13:$AF$765="○")/ROW('신규_변경부품List v4.0_vf'!$AF$13:$AF$765),),ROW('신규_변경부품List v4.0_vf'!$A8))-12,1),"")} -> 기미전자 | B16: {=IFERROR(INDEX('신규_변경부품List v4.0_vf'!$J$13:$J$765,1/LARGE(INDEX(('신규_변경부품List v4.0_vf'!$AF$13:$AF$765="○")/ROW('신규_변경부품List v4.0_vf'!$AF$13:$AF$765),),ROW('신규_변경부품List v4.0_vf'!$A8))-12,1),"")} -> Door Assembly,Sub | C16: {=IFERROR(INDEX('신규_변경부품List v4.0_vf'!$I$13:$I$765,1/LARGE(INDEX(('신규_변경부품List v4.0_vf'!$AF$13:$AF$765="○")/ROW('신규_변경부품List v4.0_vf'!$AF$13:$AF$765),),ROW('신규_변경부품List v4.0_vf'!$A8))-12,1),"")} -> ADC30051709 | D16: =COUNTIF($C$1:$C15,C16) -> 0 | E16: {=IFERROR(INDEX('신규_변경부품List v4.0_vf'!Y$13:Y$765,1/LARGE(INDEX(('신규_변경부품List v4.0_vf'!$AF$13:$AF$765="○")/ROW('신규_변경부품List v4.0_vf'!$AF$13:$AF$765),),ROW('신규_변경부품List v4.0_vf'!$A8))-12,1),"")} -> c | F16: {=IFERROR(INDEX('신규_변경부품List v4.0_vf'!Z$13:Z$765,1/LARGE(INDEX(('신규_변경부품List v4.0_vf'!$AF$13:$AF$765="○")/ROW('신규_변경부품List v4.0_vf'!$AF$13:$AF$765),),ROW('신규_변경부품List v4.0_vf'!$A8))-12,1),"")} -> x | G16: {=IFERROR(INDEX('신규_변경부품List v4.0_vf'!AA$13:AA$765,1/LARGE(INDEX(('신규_변경부품List v4.0_vf'!$AF$13:$AF$765="○")/ROW('신규_변경부품List v4.0_vf'!$AF$13:$AF$765),),ROW('신규_변경부품List v4.0_vf'!$A8))-12,1),"")} -> x | H16: {=IFERROR(INDEX('신규_변경부품List v4.0_vf'!AB$13:AB$765,1/LARGE(INDEX(('신규_변경부품List v4.0_vf'!$AF$13:$AF$765="○")/ROW('신규_변경부품List v4.0_vf'!$AF$13:$AF$765),),ROW('신규_변경부품List v4.0_vf'!$A8))-12,1),"")} -> x | I16: {=IFERROR(INDEX('신규_변경부품List v4.0_vf'!AC$13:AC$765,1/LARGE(INDEX(('신규_변경부품List v4.0_vf'!$AF$13:$AF$765="○")/ROW('신규_변경부품List v4.0_vf'!$AF$13:$AF$765),),ROW('신규_변경부품List v4.0_vf'!$A8))-12,1),"")} -> x | J16: {=IFERROR(INDEX('신규_변경부품List v4.0_vf'!AD$13:AD$765,1/LARGE(INDEX(('신규_변경부품List v4.0_vf'!$AF$13:$AF$765="○")/ROW('신규_변경부품List v4.0_vf'!$AF$13:$AF$765),),ROW('신규_변경부품List v4.0_vf'!$A8))-12,1),"")} -> x | K16: {=IFERROR(INDEX('신규_변경부품List v4.0_vf'!AE$13:AE$765,1/LARGE(INDEX(('신규_변경부품List v4.0_vf'!$AF$13:$AF$765="○")/ROW('신규_변경부품List v4.0_vf'!$AF$13:$AF$765),),ROW('신규_변경부품List v4.0_vf'!$A8))-12,1),"")} -> x | L16: {=IFERROR(INDEX('신규_변경부품List v4.0_vf'!AF$13:AF$765,1/LARGE(INDEX(('신규_변경부품List v4.0_vf'!$AF$13:$AF$765="○")/ROW('신규_변경부품List v4.0_vf'!$AF$13:$AF$765),),ROW('신규_변경부품List v4.0_vf'!$A8))-12,1),"")} -> ○ | ... N16: {=IFERROR(INDEX('신규_변경부품List v4.0_vf'!AH$13:AH$765,1/LARGE(INDEX(('신규_변경부품List v4.0_vf'!$AF$13:$AF$765="○")/ROW('신규_변경부품List v4.0_vf'!$AF$13:$AF$765),),ROW('신규_변경부품List v4.0_vf'!$A8))-12,1),"")} -> 기존 거래 업체 / 기존 공법 / 기존 재질 적용된 단순 하위 부품 변경 으로 c급 선정
A17: {=IFERROR(INDEX('신규_변경부품List v4.0_vf'!$W$13:$W$765,1/LARGE(INDEX(('신규_변경부품List v4.0_vf'!$AF$13:$AF$765="○")/ROW('신규_변경부품List v4.0_vf'!$AF$13:$AF$765),),ROW('신규_변경부품List v4.0_vf'!$A9))-12,1),"")} -> 기미전자 | B17: {=IFERROR(INDEX('신규_변경부품List v4.0_vf'!$J$13:$J$765,1/LARGE(INDEX(('신규_변경부품List v4.0_vf'!$AF$13:$AF$765="○")/ROW('신규_변경부품List v4.0_vf'!$AF$13:$AF$765),),ROW('신규_변경부품List v4.0_vf'!$A9))-12,1),"")} -> Decor,Front | C17: {=IFERROR(INDEX('신규_변경부품List v4.0_vf'!$I$13:$I$765,1/LARGE(INDEX(('신규_변경부품List v4.0_vf'!$AF$13:$AF$765="○")/ROW('신규_변경부품List v4.0_vf'!$AF$13:$AF$765),),ROW('신규_변경부품List v4.0_vf'!$A9))-12,1),"")} -> MCR68408206 | D17: =COUNTIF($C$1:$C16,C17) -> 0 | E17: {=IFERROR(INDEX('신규_변경부품List v4.0_vf'!Y$13:Y$765,1/LARGE(INDEX(('신규_변경부품List v4.0_vf'!$AF$13:$AF$765="○")/ROW('신규_변경부품List v4.0_vf'!$AF$13:$AF$765),),ROW('신규_변경부품List v4.0_vf'!$A9))-12,1),"")} -> c | F17: {=IFERROR(INDEX('신규_변경부품List v4.0_vf'!Z$13:Z$765,1/LARGE(INDEX(('신규_변경부품List v4.0_vf'!$AF$13:$AF$765="○")/ROW('신규_변경부품List v4.0_vf'!$AF$13:$AF$765),),ROW('신규_변경부품List v4.0_vf'!$A9))-12,1),"")} -> x | G17: {=IFERROR(INDEX('신규_변경부품List v4.0_vf'!AA$13:AA$765,1/LARGE(INDEX(('신규_변경부품List v4.0_vf'!$AF$13:$AF$765="○")/ROW('신규_변경부품List v4.0_vf'!$AF$13:$AF$765),),ROW('신규_변경부품List v4.0_vf'!$A9))-12,1),"")} -> x | H17: {=IFERROR(INDEX('신규_변경부품List v4.0_vf'!AB$13:AB$765,1/LARGE(INDEX(('신규_변경부품List v4.0_vf'!$AF$13:$AF$765="○")/ROW('신규_변경부품List v4.0_vf'!$AF$13:$AF$765),),ROW('신규_변경부품List v4.0_vf'!$A9))-12,1),"")} -> x | I17: {=IFERROR(INDEX('신규_변경부품List v4.0_vf'!AC$13:AC$765,1/LARGE(INDEX(('신규_변경부품List v4.0_vf'!$AF$13:$AF$765="○")/ROW('신규_변경부품List v4.0_vf'!$AF$13:$AF$765),),ROW('신규_변경부품List v4.0_vf'!$A9))-12,1),"")} -> x | J17: {=IFERROR(INDEX('신규_변경부품List v4.0_vf'!AD$13:AD$765,1/LARGE(INDEX(('신규_변경부품List v4.0_vf'!$AF$13:$AF$765="○")/ROW('신규_변경부품List v4.0_vf'!$AF$13:$AF$765),),ROW('신규_변경부품List v4.0_vf'!$A9))-12,1),"")} -> x | K17: {=IFERROR(INDEX('신규_변경부품List v4.0_vf'!AE$13:AE$765,1/LARGE(INDEX(('신규_변경부품List v4.0_vf'!$AF$13:$AF$765="○")/ROW('신규_변경부품List v4.0_vf'!$AF$13:$AF$765),),ROW('신규_변경부품List v4.0_vf'!$A9))-12,1),"")} -> x | L17: {=IFERROR(INDEX('신규_변경부품List v4.0_vf'!AF$13:AF$765,1/LARGE(INDEX(('신규_변경부품List v4.0_vf'!$AF$13:$AF$765="○")/ROW('신규_변경부품List v4.0_vf'!$AF$13:$AF$765),),ROW('신규_변경부품List v4.0_vf'!$A9))-12,1),"")} -> ○ | ... N17: {=IFERROR(INDEX('신규_변경부품List v4.0_vf'!AH$13:AH$765,1/LARGE(INDEX(('신규_변경부품List v4.0_vf'!$AF$13:$AF$765="○")/ROW('신규_변경부품List v4.0_vf'!$AF$13:$AF$765),),ROW('신규_변경부품List v4.0_vf'!$A9))-12,1),"")} -> 기존 거래 업체 / 기존 공법 / 기존 재질 적용된 단순 하위 부품 변경 으로 c급 선정
A18: {=IFERROR(INDEX('신규_변경부품List v4.0_vf'!$W$13:$W$765,1/LARGE(INDEX(('신규_변경부품List v4.0_vf'!$AF$13:$AF$765="○")/ROW('신규_변경부품List v4.0_vf'!$AF$13:$AF$765),),ROW('신규_변경부품List v4.0_vf'!$A10))-12,1),"")} -> 에스디이앤티(한덕) | B18: {=IFERROR(INDEX('신규_변경부품List v4.0_vf'!$J$13:$J$765,1/LARGE(INDEX(('신규_변경부품List v4.0_vf'!$AF$13:$AF$765="○")/ROW('신규_변경부품List v4.0_vf'!$AF$13:$AF$765),),ROW('신규_변경부품List v4.0_vf'!$A10))-12,1),"")} -> Handle,Door | C18: {=IFERROR(INDEX('신규_변경부품List v4.0_vf'!$I$13:$I$765,1/LARGE(INDEX(('신규_변경부품List v4.0_vf'!$AF$13:$AF$765="○")/ROW('신규_변경부품List v4.0_vf'!$AF$13:$AF$765),),ROW('신규_변경부품List v4.0_vf'!$A10))-12,1),"")} -> AED30153303 | D18: =COUNTIF($C$1:$C17,C18) -> 1 | E18: {=IFERROR(INDEX('신규_변경부품List v4.0_vf'!Y$13:Y$765,1/LARGE(INDEX(('신규_변경부품List v4.0_vf'!$AF$13:$AF$765="○")/ROW('신규_변경부품List v4.0_vf'!$AF$13:$AF$765),),ROW('신규_변경부품List v4.0_vf'!$A10))-12,1),"")} -> c | F18: {=IFERROR(INDEX('신규_변경부품List v4.0_vf'!Z$13:Z$765,1/LARGE(INDEX(('신규_변경부품List v4.0_vf'!$AF$13:$AF$765="○")/ROW('신규_변경부품List v4.0_vf'!$AF$13:$AF$765),),ROW('신규_변경부품List v4.0_vf'!$A10))-12,1),"")} -> x | G18: {=IFERROR(INDEX('신규_변경부품List v4.0_vf'!AA$13:AA$765,1/LARGE(INDEX(('신규_변경부품List v4.0_vf'!$AF$13:$AF$765="○")/ROW('신규_변경부품List v4.0_vf'!$AF$13:$AF$765),),ROW('신규_변경부품List v4.0_vf'!$A10))-12,1),"")} -> x | H18: {=IFERROR(INDEX('신규_변경부품List v4.0_vf'!AB$13:AB$765,1/LARGE(INDEX(('신규_변경부품List v4.0_vf'!$AF$13:$AF$765="○")/ROW('신규_변경부품List v4.0_vf'!$AF$13:$AF$765),),ROW('신규_변경부품List v4.0_vf'!$A10))-12,1),"")} -> x | I18: {=IFERROR(INDEX('신규_변경부품List v4.0_vf'!AC$13:AC$765,1/LARGE(INDEX(('신규_변경부품List v4.0_vf'!$AF$13:$AF$765="○")/ROW('신규_변경부품List v4.0_vf'!$AF$13:$AF$765),),ROW('신규_변경부품List v4.0_vf'!$A10))-12,1),"")} -> x | J18: {=IFERROR(INDEX('신규_변경부품List v4.0_vf'!AD$13:AD$765,1/LARGE(INDEX(('신규_변경부품List v4.0_vf'!$AF$13:$AF$765="○")/ROW('신규_변경부품List v4.0_vf'!$AF$13:$AF$765),),ROW('신규_변경부품List v4.0_vf'!$A10))-12,1),"")} -> x | K18: {=IFERROR(INDEX('신규_변경부품List v4.0_vf'!AE$13:AE$765,1/LARGE(INDEX(('신규_변경부품List v4.0_vf'!$AF$13:$AF$765="○")/ROW('신규_변경부품List v4.0_vf'!$AF$13:$AF$765),),ROW('신규_변경부품List v4.0_vf'!$A10))-12,1),"")} -> x | L18: {=IFERROR(INDEX('신규_변경부품List v4.0_vf'!AF$13:AF$765,1/LARGE(INDEX(('신규_변경부품List v4.0_vf'!$AF$13:$AF$765="○")/ROW('신규_변경부품List v4.0_vf'!$AF$13:$AF$765),),ROW('신규_변경부품List v4.0_vf'!$A10))-12,1),"")} -> ○ | ... N18: {=IFERROR(INDEX('신규_변경부품List v4.0_vf'!AH$13:AH$765,1/LARGE(INDEX(('신규_변경부품List v4.0_vf'!$AF$13:$AF$765="○")/ROW('신규_변경부품List v4.0_vf'!$AF$13:$AF$765),),ROW('신규_변경부품List v4.0_vf'!$A10))-12,1),"")} -> 기존 거래 업체 / 기존 공법 / 기존 재질 적용된 단순 하위 부품 변경 으로 c급 선정
A19: {=IFERROR(INDEX('신규_변경부품List v4.0_vf'!$W$13:$W$765,1/LARGE(INDEX(('신규_변경부품List v4.0_vf'!$AF$13:$AF$765="○")/ROW('신규_변경부품List v4.0_vf'!$AF$13:$AF$765),),ROW('신규_변경부품List v4.0_vf'!$A11))-12,1),"")} -> 에스디이앤티(한덕) | B19: {=IFERROR(INDEX('신규_변경부품List v4.0_vf'!$J$13:$J$765,1/LARGE(INDEX(('신규_변경부품List v4.0_vf'!$AF$13:$AF$765="○")/ROW('신규_변경부품List v4.0_vf'!$AF$13:$AF$765),),ROW('신규_변경부품List v4.0_vf'!$A11))-12,1),"")} -> Holder,Bracket | C19: {=IFERROR(INDEX('신규_변경부품List v4.0_vf'!$I$13:$I$765,1/LARGE(INDEX(('신규_변경부품List v4.0_vf'!$AF$13:$AF$765="○")/ROW('신규_변경부품List v4.0_vf'!$AF$13:$AF$765),),ROW('신규_변경부품List v4.0_vf'!$A11))-12,1),"")} -> MEG66749803 | D19: =COUNTIF($C$1:$C18,C19) -> 1 | E19: {=IFERROR(INDEX('신규_변경부품List v4.0_vf'!Y$13:Y$765,1/LARGE(INDEX(('신규_변경부품List v4.0_vf'!$AF$13:$AF$765="○")/ROW('신규_변경부품List v4.0_vf'!$AF$13:$AF$765),),ROW('신규_변경부품List v4.0_vf'!$A11))-12,1),"")} -> c | F19: {=IFERROR(INDEX('신규_변경부품List v4.0_vf'!Z$13:Z$765,1/LARGE(INDEX(('신규_변경부품List v4.0_vf'!$AF$13:$AF$765="○")/ROW('신규_변경부품List v4.0_vf'!$AF$13:$AF$765),),ROW('신규_변경부품List v4.0_vf'!$A11))-12,1),"")} -> x | G19: {=IFERROR(INDEX('신규_변경부품List v4.0_vf'!AA$13:AA$765,1/LARGE(INDEX(('신규_변경부품List v4.0_vf'!$AF$13:$AF$765="○")/ROW('신규_변경부품List v4.0_vf'!$AF$13:$AF$765),),ROW('신규_변경부품List v4.0_vf'!$A11))-12,1),"")} -> x | H19: {=IFERROR(INDEX('신규_변경부품List v4.0_vf'!AB$13:AB$765,1/LARGE(INDEX(('신규_변경부품List v4.0_vf'!$AF$13:$AF$765="○")/ROW('신규_변경부품List v4.0_vf'!$AF$13:$AF$765),),ROW('신규_변경부품List v4.0_vf'!$A11))-12,1),"")} -> x | I19: {=IFERROR(INDEX('신규_변경부품List v4.0_vf'!AC$13:AC$765,1/LARGE(INDEX(('신규_변경부품List v4.0_vf'!$AF$13:$AF$765="○")/ROW('신규_변경부품List v4.0_vf'!$AF$13:$AF$765),),ROW('신규_변경부품List v4.0_vf'!$A11))-12,1),"")} -> x | J19: {=IFERROR(INDEX('신규_변경부품List v4.0_vf'!AD$13:AD$765,1/LARGE(INDEX(('신규_변경부품List v4.0_vf'!$AF$13:$AF$765="○")/ROW('신규_변경부품List v4.0_vf'!$AF$13:$AF$765),),ROW('신규_변경부품List v4.0_vf'!$A11))-12,1),"")} -> x | K19: {=IFERROR(INDEX('신규_변경부품List v4.0_vf'!AE$13:AE$765,1/LARGE(INDEX(('신규_변경부품List v4.0_vf'!$AF$13:$AF$765="○")/ROW('신규_변경부품List v4.0_vf'!$AF$13:$AF$765),),ROW('신규_변경부품List v4.0_vf'!$A11))-12,1),"")} -> x | L19: {=IFERROR(INDEX('신규_변경부품List v4.0_vf'!AF$13:AF$765,1/LARGE(INDEX(('신규_변경부품List v4.0_vf'!$AF$13:$AF$765="○")/ROW('신규_변경부품List v4.0_vf'!$AF$13:$AF$765),),ROW('신규_변경부품List v4.0_vf'!$A11))-12,1),"")} -> ○ | ... N19: {=IFERROR(INDEX('신규_변경부품List v4.0_vf'!AH$13:AH$765,1/LARGE(INDEX(('신규_변경부품List v4.0_vf'!$AF$13:$AF$765="○")/ROW('신규_변경부품List v4.0_vf'!$AF$13:$AF$765),),ROW('신규_변경부품List v4.0_vf'!$A11))-12,1),"")} -> 기존 거래 업체 / 기존 공법 / 기존 재질 적용된 단순 하위 부품 변경 으로 c급 선정
A20: {=IFERROR(INDEX('신규_변경부품List v4.0_vf'!$W$13:$W$765,1/LARGE(INDEX(('신규_변경부품List v4.0_vf'!$AF$13:$AF$765="○")/ROW('신규_변경부품List v4.0_vf'!$AF$13:$AF$765),),ROW('신규_변경부품List v4.0_vf'!$A12))-12,1),"")} -> 신신사 | B20: {=IFERROR(INDEX('신규_변경부품List v4.0_vf'!$J$13:$J$765,1/LARGE(INDEX(('신규_변경부품List v4.0_vf'!$AF$13:$AF$765="○")/ROW('신규_변경부품List v4.0_vf'!$AF$13:$AF$765),),ROW('신규_변경부품List v4.0_vf'!$A12))-12,1),"")} -> Controller Assembly,Mechanical | C20: {=IFERROR(INDEX('신규_변경부품List v4.0_vf'!$I$13:$I$765,1/LARGE(INDEX(('신규_변경부품List v4.0_vf'!$AF$13:$AF$765="○")/ROW('신규_변경부품List v4.0_vf'!$AF$13:$AF$765),),ROW('신규_변경부품List v4.0_vf'!$A12))-12,1),"")} -> ACM76195078 | D20: =COUNTIF($C$1:$C19,C20) -> 0 | E20: {=IFERROR(INDEX('신규_변경부품List v4.0_vf'!Y$13:Y$765,1/LARGE(INDEX(('신규_변경부품List v4.0_vf'!$AF$13:$AF$765="○")/ROW('신규_변경부품List v4.0_vf'!$AF$13:$AF$765),),ROW('신규_변경부품List v4.0_vf'!$A12))-12,1),"")} -> c | F20: {=IFERROR(INDEX('신규_변경부품List v4.0_vf'!Z$13:Z$765,1/LARGE(INDEX(('신규_변경부품List v4.0_vf'!$AF$13:$AF$765="○")/ROW('신규_변경부품List v4.0_vf'!$AF$13:$AF$765),),ROW('신규_변경부품List v4.0_vf'!$A12))-12,1),"")} -> x | G20: {=IFERROR(INDEX('신규_변경부품List v4.0_vf'!AA$13:AA$765,1/LARGE(INDEX(('신규_변경부품List v4.0_vf'!$AF$13:$AF$765="○")/ROW('신규_변경부품List v4.0_vf'!$AF$13:$AF$765),),ROW('신규_변경부품List v4.0_vf'!$A12))-12,1),"")} -> x | H20: {=IFERROR(INDEX('신규_변경부품List v4.0_vf'!AB$13:AB$765,1/LARGE(INDEX(('신규_변경부품List v4.0_vf'!$AF$13:$AF$765="○")/ROW('신규_변경부품List v4.0_vf'!$AF$13:$AF$765),),ROW('신규_변경부품List v4.0_vf'!$A12))-12,1),"")} -> x | I20: {=IFERROR(INDEX('신규_변경부품List v4.0_vf'!AC$13:AC$765,1/LARGE(INDEX(('신규_변경부품List v4.0_vf'!$AF$13:$AF$765="○")/ROW('신규_변경부품List v4.0_vf'!$AF$13:$AF$765),),ROW('신규_변경부품List v4.0_vf'!$A12))-12,1),"")} -> x | J20: {=IFERROR(INDEX('신규_변경부품List v4.0_vf'!AD$13:AD$765,1/LARGE(INDEX(('신규_변경부품List v4.0_vf'!$AF$13:$AF$765="○")/ROW('신규_변경부품List v4.0_vf'!$AF$13:$AF$765),),ROW('신규_변경부품List v4.0_vf'!$A12))-12,1),"")} -> x | K20: {=IFERROR(INDEX('신규_변경부품List v4.0_vf'!AE$13:AE$765,1/LARGE(INDEX(('신규_변경부품List v4.0_vf'!$AF$13:$AF$765="○")/ROW('신규_변경부품List v4.0_vf'!$AF$13:$AF$765),),ROW('신규_변경부품List v4.0_vf'!$A12))-12,1),"")} -> x | L20: {=IFERROR(INDEX('신규_변경부품List v4.0_vf'!AF$13:AF$765,1/LARGE(INDEX(('신규_변경부품List v4.0_vf'!$AF$13:$AF$765="○")/ROW('신규_변경부품List v4.0_vf'!$AF$13:$AF$765),),ROW('신규_변경부품List v4.0_vf'!$A12))-12,1),"")} -> ○ | ... N20: {=IFERROR(INDEX('신규_변경부품List v4.0_vf'!AH$13:AH$765,1/LARGE(INDEX(('신규_변경부품List v4.0_vf'!$AF$13:$AF$765="○")/ROW('신규_변경부품List v4.0_vf'!$AF$13:$AF$765),),ROW('신규_변경부품List v4.0_vf'!$A12))-12,1),"")} -> 기존 거래 업체 / 기존 공법 / 기존 재질 적용된 단순 하위 부품 변경 으로 c급 선정
... A26: {=IFERROR(INDEX('신규_변경부품List v4.0_vf'!$W$13:$W$765,1/LARGE(INDEX(('신규_변경부품List v4.0_vf'!$AF$13:$AF$765="○")/ROW('신규_변경부품List v4.0_vf'!$AF$13:$AF$765),),ROW('신규_변경부품List v4.0_vf'!$A18))-12,1),"")} -> 기미전자 | B26: {=IFERROR(INDEX('신규_변경부품List v4.0_vf'!$J$13:$J$765,1/LARGE(INDEX(('신규_변경부품List v4.0_vf'!$AF$13:$AF$765="○")/ROW('신규_변경부품List v4.0_vf'!$AF$13:$AF$765),),ROW('신규_변경부품List v4.0_vf'!$A18))-12,1),"")} -> Decor,Front | C26: {=IFERROR(INDEX('신규_변경부품List v4.0_vf'!$I$13:$I$765,1/LARGE(INDEX(('신규_변경부품List v4.0_vf'!$AF$13:$AF$765="○")/ROW('신규_변경부품List v4.0_vf'!$AF$13:$AF$765),),ROW('신규_변경부품List v4.0_vf'!$A18))-12,1),"")} -> MCR68408309 | D26: =COUNTIF($C$1:$C25,C26) -> 1 | E26: {=IFERROR(INDEX('신규_변경부품List v4.0_vf'!Y$13:Y$765,1/LARGE(INDEX(('신규_변경부품List v4.0_vf'!$AF$13:$AF$765="○")/ROW('신규_변경부품List v4.0_vf'!$AF$13:$AF$765),),ROW('신규_변경부품List v4.0_vf'!$A18))-12,1),"")} -> c | F26: {=IFERROR(INDEX('신규_변경부품List v4.0_vf'!Z$13:Z$765,1/LARGE(INDEX(('신규_변경부품List v4.0_vf'!$AF$13:$AF$765="○")/ROW('신규_변경부품List v4.0_vf'!$AF$13:$AF$765),),ROW('신규_변경부품List v4.0_vf'!$A18))-12,1),"")} -> x | G26: {=IFERROR(INDEX('신규_변경부품List v4.0_vf'!AA$13:AA$765,1/LARGE(INDEX(('신규_변경부품List v4.0_vf'!$AF$13:$AF$765="○")/ROW('신규_변경부품List v4.0_vf'!$AF$13:$AF$765),),ROW('신규_변경부품List v4.0_vf'!$A18))-12,1),"")} -> x | H26: {=IFERROR(INDEX('신규_변경부품List v4.0_vf'!AB$13:AB$765,1/LARGE(INDEX(('신규_변경부품List v4.0_vf'!$AF$13:$AF$765="○")/ROW('신규_변경부품List v4.0_vf'!$AF$13:$AF$765),),ROW('신규_변경부품List v4.0_vf'!$A18))-12,1),"")} -> x | I26: {=IFERROR(INDEX('신규_변경부품List v4.0_vf'!AC$13:AC$765,1/LARGE(INDEX(('신규_변경부품List v4.0_vf'!$AF$13:$AF$765="○")/ROW('신규_변경부품List v4.0_vf'!$AF$13:$AF$765),),ROW('신규_변경부품List v4.0_vf'!$A18))-12,1),"")} -> x | J26: {=IFERROR(INDEX('신규_변경부품List v4.0_vf'!AD$13:AD$765,1/LARGE(INDEX(('신규_변경부품List v4.0_vf'!$AF$13:$AF$765="○")/ROW('신규_변경부품List v4.0_vf'!$AF$13:$AF$765),),ROW('신규_변경부품List v4.0_vf'!$A18))-12,1),"")} -> x | K26: {=IFERROR(INDEX('신규_변경부품List v4.0_vf'!AE$13:AE$765,1/LARGE(INDEX(('신규_변경부품List v4.0_vf'!$AF$13:$AF$765="○")/ROW('신규_변경부품List v4.0_vf'!$AF$13:$AF$765),),ROW('신규_변경부품List v4.0_vf'!$A18))-12,1),"")} -> x | L26: {=IFERROR(INDEX('신규_변경부품List v4.0_vf'!AF$13:AF$765,1/LARGE(INDEX(('신규_변경부품List v4.0_vf'!$AF$13:$AF$765="○")/ROW('신규_변경부품List v4.0_vf'!$AF$13:$AF$765),),ROW('신규_변경부품List v4.0_vf'!$A18))-12,1),"")} -> ○ | ... N26: {=IFERROR(INDEX('신규_변경부품List v4.0_vf'!AH$13:AH$765,1/LARGE(INDEX(('신규_변경부품List v4.0_vf'!$AF$13:$AF$765="○")/ROW('신규_변경부품List v4.0_vf'!$AF$13:$AF$765),),ROW('신규_변경부품List v4.0_vf'!$A18))-12,1),"")} -> 기존 거래 업체 / 기존 공법 / 기존 재질 적용된 단순 하위 부품 변경 으로 c급 선정
A27: {=IFERROR(INDEX('신규_변경부품List v4.0_vf'!$W$13:$W$765,1/LARGE(INDEX(('신규_변경부품List v4.0_vf'!$AF$13:$AF$765="○")/ROW('신규_변경부품List v4.0_vf'!$AF$13:$AF$765),),ROW('신규_변경부품List v4.0_vf'!$A19))-12,1),"")} | B27: {=IFERROR(INDEX('신규_변경부품List v4.0_vf'!$J$13:$J$765,1/LARGE(INDEX(('신규_변경부품List v4.0_vf'!$AF$13:$AF$765="○")/ROW('신규_변경부품List v4.0_vf'!$AF$13:$AF$765),),ROW('신규_변경부품List v4.0_vf'!$A19))-12,1),"")} | C27: {=IFERROR(INDEX('신규_변경부품List v4.0_vf'!$I$13:$I$765,1/LARGE(INDEX(('신규_변경부품List v4.0_vf'!$AF$13:$AF$765="○")/ROW('신규_변경부품List v4.0_vf'!$AF$13:$AF$765),),ROW('신규_변경부품List v4.0_vf'!$A19))-12,1),"")} | E27: {=IFERROR(INDEX('신규_변경부품List v4.0_vf'!Y$13:Y$765,1/LARGE(INDEX(('신규_변경부품List v4.0_vf'!$AF$13:$AF$765="○")/ROW('신규_변경부품List v4.0_vf'!$AF$13:$AF$765),),ROW('신규_변경부품List v4.0_vf'!$A19))-12,1),"")} | F27: {=IFERROR(INDEX('신규_변경부품List v4.0_vf'!Z$13:Z$765,1/LARGE(INDEX(('신규_변경부품List v4.0_vf'!$AF$13:$AF$765="○")/ROW('신규_변경부품List v4.0_vf'!$AF$13:$AF$765),),ROW('신규_변경부품List v4.0_vf'!$A19))-12,1),"")} | G27: {=IFERROR(INDEX('신규_변경부품List v4.0_vf'!AA$13:AA$765,1/LARGE(INDEX(('신규_변경부품List v4.0_vf'!$AF$13:$AF$765="○")/ROW('신규_변경부품List v4.0_vf'!$AF$13:$AF$765),),ROW('신규_변경부품List v4.0_vf'!$A19))-12,1),"")} | H27: {=IFERROR(INDEX('신규_변경부품List v4.0_vf'!AB$13:AB$765,1/LARGE(INDEX(('신규_변경부품List v4.0_vf'!$AF$13:$AF$765="○")/ROW('신규_변경부품List v4.0_vf'!$AF$13:$AF$765),),ROW('신규_변경부품List v4.0_vf'!$A19))-12,1),"")} | I27: {=IFERROR(INDEX('신규_변경부품List v4.0_vf'!AC$13:AC$765,1/LARGE(INDEX(('신규_변경부품List v4.0_vf'!$AF$13:$AF$765="○")/ROW('신규_변경부품List v4.0_vf'!$AF$13:$AF$765),),ROW('신규_변경부품List v4.0_vf'!$A19))-12,1),"")} | J27: {=IFERROR(INDEX('신규_변경부품List v4.0_vf'!AD$13:AD$765,1/LARGE(INDEX(('신규_변경부품List v4.0_vf'!$AF$13:$AF$765="○")/ROW('신규_변경부품List v4.0_vf'!$AF$13:$AF$765),),ROW('신규_변경부품List v4.0_vf'!$A19))-12,1),"")} | K27: {=IFERROR(INDEX('신규_변경부품List v4.0_vf'!AE$13:AE$765,1/LARGE(INDEX(('신규_변경부품List v4.0_vf'!$AF$13:$AF$765="○")/ROW('신규_변경부품List v4.0_vf'!$AF$13:$AF$765),),ROW('신규_변경부품List v4.0_vf'!$A19))-12,1),"")} | L27: {=IFERROR(INDEX('신규_변경부품List v4.0_vf'!AF$13:AF$765,1/LARGE(INDEX(('신규_변경부품List v4.0_vf'!$AF$13:$AF$765="○")/ROW('신규_변경부품List v4.0_vf'!$AF$13:$AF$765),),ROW('신규_변경부품List v4.0_vf'!$A19))-12,1),"")} | ... N27: {=IFERROR(INDEX('신규_변경부품List v4.0_vf'!AH$13:AH$765,1/LARGE(INDEX(('신규_변경부품List v4.0_vf'!$AF$13:$AF$765="○")/ROW('신규_변경부품List v4.0_vf'!$AF$13:$AF$765),),ROW('신규_변경부품List v4.0_vf'!$A19))-12,1),"")}
A28: {=IFERROR(INDEX('신규_변경부품List v4.0_vf'!$W$13:$W$765,1/LARGE(INDEX(('신규_변경부품List v4.0_vf'!$AF$13:$AF$765="○")/ROW('신규_변경부품List v4.0_vf'!$AF$13:$AF$765),),ROW('신규_변경부품List v4.0_vf'!$A20))-12,1),"")} | B28: {=IFERROR(INDEX('신규_변경부품List v4.0_vf'!$J$13:$J$765,1/LARGE(INDEX(('신규_변경부품List v4.0_vf'!$AF$13:$AF$765="○")/ROW('신규_변경부품List v4.0_vf'!$AF$13:$AF$765),),ROW('신규_변경부품List v4.0_vf'!$A20))-12,1),"")} | C28: {=IFERROR(INDEX('신규_변경부품List v4.0_vf'!$I$13:$I$765,1/LARGE(INDEX(('신규_변경부품List v4.0_vf'!$AF$13:$AF$765="○")/ROW('신규_변경부품List v4.0_vf'!$AF$13:$AF$765),),ROW('신규_변경부품List v4.0_vf'!$A20))-12,1),"")} | E28: {=IFERROR(INDEX('신규_변경부품List v4.0_vf'!Y$13:Y$765,1/LARGE(INDEX(('신규_변경부품List v4.0_vf'!$AF$13:$AF$765="○")/ROW('신규_변경부품List v4.0_vf'!$AF$13:$AF$765),),ROW('신규_변경부품List v4.0_vf'!$A20))-12,1),"")} | F28: {=IFERROR(INDEX('신규_변경부품List v4.0_vf'!Z$13:Z$765,1/LARGE(INDEX(('신규_변경부품List v4.0_vf'!$AF$13:$AF$765="○")/ROW('신규_변경부품List v4.0_vf'!$AF$13:$AF$765),),ROW('신규_변경부품List v4.0_vf'!$A20))-12,1),"")} | G28: {=IFERROR(INDEX('신규_변경부품List v4.0_vf'!AA$13:AA$765,1/LARGE(INDEX(('신규_변경부품List v4.0_vf'!$AF$13:$AF$765="○")/ROW('신규_변경부품List v4.0_vf'!$AF$13:$AF$765),),ROW('신규_변경부품List v4.0_vf'!$A20))-12,1),"")} | H28: {=IFERROR(INDEX('신규_변경부품List v4.0_vf'!AB$13:AB$765,1/LARGE(INDEX(('신규_변경부품List v4.0_vf'!$AF$13:$AF$765="○")/ROW('신규_변경부품List v4.0_vf'!$AF$13:$AF$765),),ROW('신규_변경부품List v4.0_vf'!$A20))-12,1),"")} | I28: {=IFERROR(INDEX('신규_변경부품List v4.0_vf'!AC$13:AC$765,1/LARGE(INDEX(('신규_변경부품List v4.0_vf'!$AF$13:$AF$765="○")/ROW('신규_변경부품List v4.0_vf'!$AF$13:$AF$765),),ROW('신규_변경부품List v4.0_vf'!$A20))-12,1),"")} | J28: {=IFERROR(INDEX('신규_변경부품List v4.0_vf'!AD$13:AD$765,1/LARGE(INDEX(('신규_변경부품List v4.0_vf'!$AF$13:$AF$765="○")/ROW('신규_변경부품List v4.0_vf'!$AF$13:$AF$765),),ROW('신규_변경부품List v4.0_vf'!$A20))-12,1),"")} | K28: {=IFERROR(INDEX('신규_변경부품List v4.0_vf'!AE$13:AE$765,1/LARGE(INDEX(('신규_변경부품List v4.0_vf'!$AF$13:$AF$765="○")/ROW('신규_변경부품List v4.0_vf'!$AF$13:$AF$765),),ROW('신규_변경부품List v4.0_vf'!$A20))-12,1),"")} | L28: {=IFERROR(INDEX('신규_변경부품List v4.0_vf'!AF$13:AF$765,1/LARGE(INDEX(('신규_변경부품List v4.0_vf'!$AF$13:$AF$765="○")/ROW('신규_변경부품List v4.0_vf'!$AF$13:$AF$765),),ROW('신규_변경부품List v4.0_vf'!$A20))-12,1),"")} | ... N28: {=IFERROR(INDEX('신규_변경부품List v4.0_vf'!AH$13:AH$765,1/LARGE(INDEX(('신규_변경부품List v4.0_vf'!$AF$13:$AF$765="○")/ROW('신규_변경부품List v4.0_vf'!$AF$13:$AF$765),),ROW('신규_변경부품List v4.0_vf'!$A20))-12,1),"")}
A29: {=IFERROR(INDEX('신규_변경부품List v4.0_vf'!$W$13:$W$765,1/LARGE(INDEX(('신규_변경부품List v4.0_vf'!$AF$13:$AF$765="○")/ROW('신규_변경부품List v4.0_vf'!$AF$13:$AF$765),),ROW('신규_변경부품List v4.0_vf'!$A21))-12,1),"")} | B29: {=IFERROR(INDEX('신규_변경부품List v4.0_vf'!$J$13:$J$765,1/LARGE(INDEX(('신규_변경부품List v4.0_vf'!$AF$13:$AF$765="○")/ROW('신규_변경부품List v4.0_vf'!$AF$13:$AF$765),),ROW('신규_변경부품List v4.0_vf'!$A21))-12,1),"")} | C29: {=IFERROR(INDEX('신규_변경부품List v4.0_vf'!$I$13:$I$765,1/LARGE(INDEX(('신규_변경부품List v4.0_vf'!$AF$13:$AF$765="○")/ROW('신규_변경부품List v4.0_vf'!$AF$13:$AF$765),),ROW('신규_변경부품List v4.0_vf'!$A21))-12,1),"")} | E29: {=IFERROR(INDEX('신규_변경부품List v4.0_vf'!Y$13:Y$765,1/LARGE(INDEX(('신규_변경부품List v4.0_vf'!$AF$13:$AF$765="○")/ROW('신규_변경부품List v4.0_vf'!$AF$13:$AF$765),),ROW('신규_변경부품List v4.0_vf'!$A21))-12,1),"")} | F29: {=IFERROR(INDEX('신규_변경부품List v4.0_vf'!Z$13:Z$765,1/LARGE(INDEX(('신규_변경부품List v4.0_vf'!$AF$13:$AF$765="○")/ROW('신규_변경부품List v4.0_vf'!$AF$13:$AF$765),),ROW('신규_변경부품List v4.0_vf'!$A21))-12,1),"")} | G29: {=IFERROR(INDEX('신규_변경부품List v4.0_vf'!AA$13:AA$765,1/LARGE(INDEX(('신규_변경부품List v4.0_vf'!$AF$13:$AF$765="○")/ROW('신규_변경부품List v4.0_vf'!$AF$13:$AF$765),),ROW('신규_변경부품List v4.0_vf'!$A21))-12,1),"")} | H29: {=IFERROR(INDEX('신규_변경부품List v4.0_vf'!AB$13:AB$765,1/LARGE(INDEX(('신규_변경부품List v4.0_vf'!$AF$13:$AF$765="○")/ROW('신규_변경부품List v4.0_vf'!$AF$13:$AF$765),),ROW('신규_변경부품List v4.0_vf'!$A21))-12,1),"")} | I29: {=IFERROR(INDEX('신규_변경부품List v4.0_vf'!AC$13:AC$765,1/LARGE(INDEX(('신규_변경부품List v4.0_vf'!$AF$13:$AF$765="○")/ROW('신규_변경부품List v4.0_vf'!$AF$13:$AF$765),),ROW('신규_변경부품List v4.0_vf'!$A21))-12,1),"")} | J29: {=IFERROR(INDEX('신규_변경부품List v4.0_vf'!AD$13:AD$765,1/LARGE(INDEX(('신규_변경부품List v4.0_vf'!$AF$13:$AF$765="○")/ROW('신규_변경부품List v4.0_vf'!$AF$13:$AF$765),),ROW('신규_변경부품List v4.0_vf'!$A21))-12,1),"")} | K29: {=IFERROR(INDEX('신규_변경부품List v4.0_vf'!AE$13:AE$765,1/LARGE(INDEX(('신규_변경부품List v4.0_vf'!$AF$13:$AF$765="○")/ROW('신규_변경부품List v4.0_vf'!$AF$13:$AF$765),),ROW('신규_변경부품List v4.0_vf'!$A21))-12,1),"")} | L29: {=IFERROR(INDEX('신규_변경부품List v4.0_vf'!AF$13:AF$765,1/LARGE(INDEX(('신규_변경부품List v4.0_vf'!$AF$13:$AF$765="○")/ROW('신규_변경부품List v4.0_vf'!$AF$13:$AF$765),),ROW('신규_변경부품List v4.0_vf'!$A21))-12,1),"")} | ... N29: {=IFERROR(INDEX('신규_변경부품List v4.0_vf'!AH$13:AH$765,1/LARGE(INDEX(('신규_변경부품List v4.0_vf'!$AF$13:$AF$765="○")/ROW('신규_변경부품List v4.0_vf'!$AF$13:$AF$765),),ROW('신규_변경부품List v4.0_vf'!$A21))-12,1),"")}
A30: {=IFERROR(INDEX('신규_변경부품List v4.0_vf'!$W$13:$W$765,1/LARGE(INDEX(('신규_변경부품List v4.0_vf'!$AF$13:$AF$765="○")/ROW('신규_변경부품List v4.0_vf'!$AF$13:$AF$765),),ROW('신규_변경부품List v4.0_vf'!$A22))-12,1),"")} | B30: {=IFERROR(INDEX('신규_변경부품List v4.0_vf'!$J$13:$J$765,1/LARGE(INDEX(('신규_변경부품List v4.0_vf'!$AF$13:$AF$765="○")/ROW('신규_변경부품List v4.0_vf'!$AF$13:$AF$765),),ROW('신규_변경부품List v4.0_vf'!$A22))-12,1),"")} | C30: {=IFERROR(INDEX('신규_변경부품List v4.0_vf'!$I$13:$I$765,1/LARGE(INDEX(('신규_변경부품List v4.0_vf'!$AF$13:$AF$765="○")/ROW('신규_변경부품List v4.0_vf'!$AF$13:$AF$765),),ROW('신규_변경부품List v4.0_vf'!$A22))-12,1),"")}
A31: {=IFERROR(INDEX('신규_변경부품List v4.0_vf'!$W$13:$W$765,1/LARGE(INDEX(('신규_변경부품List v4.0_vf'!$AF$13:$AF$765="○")/ROW('신규_변경부품List v4.0_vf'!$AF$13:$AF$765),),ROW('신규_변경부품List v4.0_vf'!$A23))-12,1),"")} | B31: {=IFERROR(INDEX('신규_변경부품List v4.0_vf'!$J$13:$J$765,1/LARGE(INDEX(('신규_변경부품List v4.0_vf'!$AF$13:$AF$765="○")/ROW('신규_변경부품List v4.0_vf'!$AF$13:$AF$765),),ROW('신규_변경부품List v4.0_vf'!$A23))-12,1),"")} | C31: {=IFERROR(INDEX('신규_변경부품List v4.0_vf'!$I$13:$I$765,1/LARGE(INDEX(('신규_변경부품List v4.0_vf'!$AF$13:$AF$765="○")/ROW('신규_변경부품List v4.0_vf'!$AF$13:$AF$765),),ROW('신규_변경부품List v4.0_vf'!$A23))-12,1),"")}
A32: {=IFERROR(INDEX('신규_변경부품List v4.0_vf'!$W$13:$W$765,1/LARGE(INDEX(('신규_변경부품List v4.0_vf'!$AF$13:$AF$765="○")/ROW('신규_변경부품List v4.0_vf'!$AF$13:$AF$765),),ROW('신규_변경부품List v4.0_vf'!$A24))-12,1),"")} | B32: {=IFERROR(INDEX('신규_변경부품List v4.0_vf'!$J$13:$J$765,1/LARGE(INDEX(('신규_변경부품List v4.0_vf'!$AF$13:$AF$765="○")/ROW('신규_변경부품List v4.0_vf'!$AF$13:$AF$765),),ROW('신규_변경부품List v4.0_vf'!$A24))-12,1),"")} | C32: {=IFERROR(INDEX('신규_변경부품List v4.0_vf'!$I$13:$I$765,1/LARGE(INDEX(('신규_변경부품List v4.0_vf'!$AF$13:$AF$765="○")/ROW('신규_변경부품List v4.0_vf'!$AF$13:$AF$765),),ROW('신규_변경부품List v4.0_vf'!$A24))-12,1),"")}
A33: {=IFERROR(INDEX('신규_변경부품List v4.0_vf'!$W$13:$W$765,1/LARGE(INDEX(('신규_변경부품List v4.0_vf'!$AF$13:$AF$765="○")/ROW('신규_변경부품List v4.0_vf'!$AF$13:$AF$765),),ROW('신규_변경부품List v4.0_vf'!$A25))-12,1),"")} | B33: {=IFERROR(INDEX('신규_변경부품List v4.0_vf'!$J$13:$J$765,1/LARGE(INDEX(('신규_변경부품List v4.0_vf'!$AF$13:$AF$765="○")/ROW('신규_변경부품List v4.0_vf'!$AF$13:$AF$765),),ROW('신규_변경부품List v4.0_vf'!$A25))-12,1),"")} | C33: {=IFERROR(INDEX('신규_변경부품List v4.0_vf'!$I$13:$I$765,1/LARGE(INDEX(('신규_변경부품List v4.0_vf'!$AF$13:$AF$765="○")/ROW('신규_변경부품List v4.0_vf'!$AF$13:$AF$765),),ROW('신규_변경부품List v4.0_vf'!$A25))-12,1),"")}
A34: {=IFERROR(INDEX('신규_변경부품List v4.0_vf'!$W$13:$W$765,1/LARGE(INDEX(('신규_변경부품List v4.0_vf'!$F$13:$F$765="New")/ROW('신규_변경부품List v4.0_vf'!$F$13:$F$765),),ROW('신규_변경부품List v4.0_vf'!$A26))-12,1),"")} | B34: {=IFERROR(INDEX('신규_변경부품List v4.0_vf'!$J$13:$J$765,1/LARGE(INDEX(('신규_변경부품List v4.0_vf'!$F$13:$F$765="New")/ROW('신규_변경부품List v4.0_vf'!$F$13:$F$765),),ROW('신규_변경부품List v4.0_vf'!$A26))-12,1),"")} | C34: {=IFERROR(INDEX('신규_변경부품List v4.0_vf'!$I$13:$I$765,1/LARGE(INDEX(('신규_변경부품List v4.0_vf'!$F$13:$F$765="New")/ROW('신규_변경부품List v4.0_vf'!$F$13:$F$765),),ROW('신규_변경부품List v4.0_vf'!$A26))-12,1),"")}

Sheet Base Design
A1: 구분 | B1: * Base Design | C1: 개발 Model | D1: 변경 사유 | E1: 변경으로 인한 변화점 [해당부품 또는 주변/영향부품] | F1: 비고
A2: 형상 & 구조구성 | C2: 1. Ball 삭제 및 1piece 구조로 변경함 | D2: 1. Lifter단품의 Volume 축소를 통한 용량확보 | E2: 1. Inner Tub와 조립 Hook 방향 상이 1) 사유 : 1piece 구조로 변경됨에 따라 금형구조 나오지 않음 2) 체결Hook 변경으로 Drum Center Piercing Hole 형상 변경되어야 함 3) 기존 Lifter와 개발 Lifter 동시에 체결될 수 있도록 Drum Center Piercing Hole 형상 변경
A3: 기능 | B3: Inner Tub 내측에 120도 간격으로 위치하여 세탁물을 일정높이로 들어올려 1) 낙차를 발생시키며 2) 세탁물이 탈수진입전 골고루 분산될 수 있도록 함 | C3: 좌동 | D3: 기능변경 없음
A4: Input | F4: Module & system & 전장부품 (Controller포함)
A5: Output
A6: KCP
A7: KNP
A8: 치수 | B8: 287.2 X 77 X 77 | C8: 287.2 X 77 X 77
A9: 재료 | B9: PP MT42 | C9: PP MT42
A10: Base Design 이란 ?
A11: - 설계자가 zero base에서 설계를 하는 것이 아니라, 자사 또는 타사의 제품 및 부품이 어떻게 설계가 되어 있는지를 참조하는 대상을 base design 함.
A12: - 부품개발이나 수익성 비교를 위해 선정하는 base model과는 다를 수도 있고 같을 수도 있음.
A13: - 내가 설계할 때 참조를 어떤 것을 했는지, 그래서 무엇을 변경시켰는지에 대한 설명을 위해 필요한 것임

Sheet ERRC 근거_변경부품List v3.1
O1: R&D | Q1: 설계에서 작성해야 할 부분
B2: New & Changing Part Development List (Example) | O2: Mold Dev. | Q2: 금형 개발 담당자가 작성해야 할 부분
B3: Model / Grade | I3: FC HI EER -.FC75LBNA / C1 | O3: Procument/ Mfg engineer | Q3: 구매 개발을 책임지는 담당자가 작성하는 곳.
B4: Event | I4: CP PP DV PV PQ | Q4: Date of compostion: | R4: 40379 | T4: Date of revisions: | W4: 40516
B5: No. | C5: 모델 | E5: BOM Level | F5: Classification | G5: Part Type | H5: Part No. | J5: Class Desc.(Part Name) | K5: Fig. | L5: 변경점 | M5: 변경사유 | N5: Quanty | O5: 설계자 | P5: 구매/ 생기 | Q5: 변경 Level | R5: DRBFM Execution | U5: Part Grade | V5: 인쇄물 변경 | W5: Part Approval * | AB5: Confirm Drawing | AE5: Tooling Development | AK5: Part Development | AS5: Final Pass Judgment
C6: A | D6: B | H6: Base P/No | I6: New P/No | R6: Design | S6: Process | T6: Why don't you excute DRBFM? | W6: Quality Limit Sample | X6: 1st Prod. Inspection | Y6: Audit Approval | Z6: Process Inspection | AA6: Reliability test | AB6: List | AC6: Drawing agreement(DR) | AD6: Drawing Approvalto DA PLM | AE6: CAE (Mold flow) | AF6: 1st Production | AG6: Q. Pass | AH6: 금형비 | AI6: Specification | AJ6: Cavity | AK6: 양산업체 | AL6: 부품개발 담당자 | AM6: 부품개발 의뢰일 | AN6: 구매 접수일 | AO6: DQMS 진행상태 | AP6: Q. Pass | AQ6: Quality issue & F/up | AR6: Target Cost
B7: R&D | N7: R&D | AE7: Mold & Die Development Group | AK7: Procurement/ Mfg Engineer
B8: 1 | C8: ● | D8: ● | E8: ...4 | F8: New | G8: MD Part | I8: MDQ62836301 | J8: Frame,Sub | N8: 1 | O8: 박주홍 | P8: 홍길동 | Q8: 3Level | R8: ○ | S8: X | U8: C | V8: 사용설명서 (그림변경, 문구추가) | W8: X | X8: ○ | Y8: X | Z8: X | AA8: ○ | AB8: Plan | AC8: 40414 | AD8: 40414 | AE8: 40414 | AF8: 40456 | AG8: 40461 | AH8: 50000000 | AI8: Mold | AJ8: 2 | AK8: 평화기공 | AL8: 최종원S | AM8: 40417 | AN8: 40417 | AO8: Rcv.Wating | AP8: 40505 | AQ8: 측정결과:NG - 도면 현실화시방 완료(OK) | AR8: ???? | AS8: OK
AB9: Result | AC9: 40422 | AD9: 40435 | AE9: 40435 | AM9: 40417 | AN9: 40421 | AP9: 40513 | AR9: ????
B10: 2 | C10: ● | D10: ● | E10: ..3 | F10: New | G10: etc. | I10: MDQ62836401 | J10: Frame,Final | N10: 1 | O10: 박주홍 | P10: 홍길동 | Q10: 2Level | R10: X | S10: X | T10: Frame,Sub대체 | U10: C | W10: X | X10: ○ | Y10: X | Z10: X | AA10: ○ | AB10: Plan | AC10: 40414 | AD10: 40414 | AE10: NA | AF10: X | AG10: X | AH10: X | AI10: - | AJ10: - | AK10: 사내 | AL10: 이용석K | AM10: X | AN10: X | AO10: Rcv.Wating | AP10: 40505 | AQ10: 측정결과:NG - 도면 현실화시방 완료(OK) | AR10: X | AS10: OK
AB11: Result | AC11: 40424 | AD11: 40430 | AE11: NA | AF11: X | AG11: X | AH11: X | AM11: X | AN11: X | AP11: 40513 | AR11: X
B12: 3 | C12: ● | D12: ● | E12: .....6 | F12: New | G12: MD Part | I12: MCN62127201 | J12: Cylinder Material | N12: 1 | O12: 박주홍 | P12: 홍길동 | Q12: 2Level | R12: X | S12: X | T12: Frame,Sub대체 | U12: C | W12: X | X12: X | Y12: X | Z12: X | AA12: X | AB12: Plan | AC12: 40414 | AD12: 40414 | AE12: NA | AF12: 40456 | AG12: 40461 | AH12: 9500000 | AI12: Mold | AJ12: 6 | AK12: 대동씨엠 | AL12: 성영호B | AM12: X | AN12: X | AO12: Rcv.Wating | AP12: X | AQ12: 측정결과:NG - 도면 현실화시방 결재중 | AR12: X | AS12: OK
AB13: Result | AC13: 40422 | AD13: 40424 | AE13: 40424 | AM13: X | AN13: X | AP13: X | AR13: X
B14: 4 | C14: ● | D14: ● | E14: ...4 | F14: New | G14: PD Part | I14: MCK42793302 | J14: D/Cover | N14: 1 | O14: 하성호 | P14: 홍길동 | Q14: 1Level | R14: X | S14: X | T14: D/Cover Asm대체 | U14: C | W14: X | X14: ○ | Y14: X | Z14: X | AA14: ○ | AB14: Plan | AC14: 40414 | AD14: 40414 | AE14: 40414 | AF14: 40456 | AG14: 40461 | AH14: 6500000 | AI14: Press | AJ14: 1 | AK14: 진유사 | AL14: 성영호B | AM14: 40417 | AN14: 40417 | AO14: Rcv.Wating | AP14: 40505 | AQ14: 측정결과:OK | AR14: X | AS14: OK
AB15: Result | AC15: 40483 | AD15: 40490 | AE15: NA | AM15: 40431 | AN15: 40436 | AP15: 40514 | AR15: X
B16: 5 | C16: ● | D16: ● | E16: ..3 | F16: New | G16: etc. | I16: ACQ37023402 | J16: D/Cover, Assy. | N16: 1 | O16: 하성호 | P16: 홍길동 | R16: ○ | S16: X | U16: C | W16: X | X16: ○ | Y16: X | Z16: X | AA16: X | AB16: Plan | AC16: 40414 | AD16: 40414 | AE16: NA | AF16: 40456 | AG16: 40461 | AH16: 12000000 | AI16: Etc | AJ16: - | AK16: 진유사 | AL16: 서현철C | AM16: 40417 | AN16: 40417 | AO16: OK | AP16: 40505 | AQ16: OK | AR16: ???? | AS16: OK
AB17: Result | AC17: 40484 | AD17: 40490 | AE17: NA | AM17: 40424 | AN17: 40434 | AP17: 40514 | AR17: ????
B18: 6 | C18: ● | D18: ● | E18: ..3 | F18: New | G18: MD Part | I18: RAB31174306 | J18: Magnet Frame | N18: 1 | O18: 윤선기 | P18: 홍길동 | R18: X | S18: X | T18: Magnet,Sub대체 | U18: C | W18: X | X18: ○ | Y18: X | Z18: X | AA18: X | AB18: Plan | AC18: 40414 | AD18: 40414 | AE18: NA | AF18: X | AG18: X | AH18: X | AI18: Mold | AJ18: - | AK18: 신금하 | AL18: 서현철C | AM18: 40417 | AN18: 40417 | AO18: Result Writing | AP18: 40505 | AQ18: 측정결과:OK - 항목추가(CTQ) 측정완료(CTQ분석:12/1) | AR18: ???? | AS18: OK
AB19: Result | AC19: 40506 | AD19: 40506 | AE19: NA | AF19: X | AG19: X | AH19: X | AM19: 40456 | AN19: 40466 | AP19: 40509 | AR19: ????
B20: 7 | C20: ● | D20: ● | E20: ...4 | F20: New | G20: MD Part | I20: RAB31176103 | J20: Magnet | N20: 12 | O20: 윤선기 | P20: 홍길동 | R20: ○ | S20: X | U20: C | W20: X | X20: ○ | Y20: X | Z20: X | AA20: X | AB20: Plan | AC20: 40414 | AD20: 40414 | AE20: 40414 | AF20: X | AG20: X | AH20: X | AI20: Mold | AJ20: - | AK20: 삼환 | AL20: 최종원S | AM20: 40417 | AN20: 40417 | AO20: 초품불요 | AP20: 40505 | AR20: X | AS20: OK
D24: 변경 levl
D25: 5Level
D26: 4Level
D27: 3Level
D28: 2Level
D29: 1Level
AR151: 4.4444444e+163

Sheet Sheet2
B1: [ Part Risk Assessment ] 1) PRA는 개발부품의 품질 Risk를 평가하여, s-APQP 실시 여부를 결정 한다. 2) PRA는 [b] 등급 부품을 대상으로 실시한다. (필요 시 이외 등급도 실시 가능) 3) PRA 각 항목은 관련부서 담당자의 의견을 수렴하여, 항목별 평가 점수를 결정 한다. * 필요시, 기준 점수 확정에 필요한 Evidence를 추가 한다.
B2: No | C2: 항목 | D2: 평가 기준 | E2: 점수 | F2: 결과 | G2: 비고
B3: 1 | C3: 고객 영향도 | D3: 제품 외관/ 안전/ 규제 측면에서, 고객에게 미칠 영향도가 적은 부품 | E3: 3 | F3: 5
D4: 고객에게 감성적인 품질로 인식되는 부품 | E4: 5
D5: 제품의 주요 기능과 연관된 중요 부품이거나, 고객이 인지하기 쉬운 외관품질 부품 | E5: 7
D6: 안전 및 법적 규제에 영향을 미치는 부품 (안전부품, PL부품) | E6: 10
